Workbook

Sheet README
A1: DGX LLM Benchmark - data collection workbook
A4: Scope | B4: Open-weight LLMs served locally on the DGX system. Closed models (Claude, GPT, Gemini, Grok) cannot run here - benchmark those via API in a separate workbook.
A6: HOW TO USE
A7: 1. | B7: Fill Hardware_Env once per system/software-stack change. Every yellow cell is an input.
A8: 2. | B8: Fill Run_Config once per benchmark campaign. It holds the fixed experiment controls and the SLA thresholds.
A9: 3. | B9: Fill Cost_Model with your real capex/power numbers. It derives $/GPU-hour, which Perf_Results uses for $/1M tokens.
A10: 4. | B10: Curate Models - one row per model+variant you intend to run. model_key is the join key used by every other sheet.
A11: 5. | B11: Perf_Results and Quality_Results are appended by the runner script. Do not type in the black formula columns.
A12: 5a. | B12: Ollama runs: `python run_ollama_bench.py --check` first to resolve tags, then `--priority P0 --pull`. Ollama = llama.cpp = layer-split GGUF; its throughput is well below vLLM/TensorRT-LLM on the same weights. serving_stack marks every row, so never compare an Ollama row against a vLLM row as if it were the same system.
A13: 6. | B13: Summary and Cost_Model roll up automatically. Refresh/recalculate after new rows land.
A15: COLOUR LEGEND
A16: Yellow fill + blue text | B16: You fill this in. Hardcoded input.
A17: Black text | B17: Formula - do not overwrite.
A18: Green text | B18: Link to another sheet in this workbook.
A19: Grey italic row | B19: EXAMPLE row showing the expected format. Delete it, or let the runner drop it (run_id starts with 'EXAMPLE').
A21: SHEETS
A22: Parameters | B22: Data dictionary - every parameter, its unit, definition and how to measure it. Read this first.
A23: Hardware_Env | B23: DGX hardware + software stack versions. Reproducibility record.
A24: Run_Config | B24: Fixed experiment controls: sweeps, sampling params, seeds, SLA thresholds.
A25: Models | B25: Model registry: provider, country, weights, quantizations planned.
A26: Perf_Results | B26: One row per load point (model x quant x TP x concurrency x ISL/OSL). Throughput, latency, GPU, power, cost.
A27: Quality_Results | B27: One row per model x task x quantization. Accuracy and behaviour metrics.
A28: Cost_Model | B28: Capex + power -> $/GPU-hour -> $/1M output tokens per model.
A29: Summary | B29: Per-model rollup for the final comparison table.
A31: RULES THAT KEEP THE NUMBERS COMPARABLE
A32: - | B32: One variable at a time. Change quantization OR TP size OR concurrency, never two at once.
A33: - | B33: Discard warm-up requests; record warmup_requests in Run_Config.
A34: - | B34: Report percentiles (p50/p95/p99), not means. Means hide tail latency.
A35: - | B35: Same client machine, same dataset, same tokenizer for token counting across all models.
A36: - | B36: Idle the GPUs between runs and record ambient conditions - thermal throttling silently skews throughput.
A37: - | B37: Verify hf_repo_id in Models before pulling weights. Repo names drift between releases.
A39: Generated 2026-07-31 by build_workbook.py

Sheet Parameters
A1: Parameter dictionary
A2: Every measurable parameter in this benchmark. 'Core' = collect for every run; 'Optional' = collect where relevant.
A4: Category | B4: Parameter | C4: Field name | D4: Unit | E4: Definition | F4: How to measure | G4: Sheet | H4: Priority
A5: Identity | B5: Model key | C5: model_key | D5: text | E5: Unique join key for a model variant. | F5: You define it; keep it stable. | G5: Models | H5: Core
A6: Identity | B6: Provider / country | C6: provider / country | D6: text | E6: Lab and country of origin - the US vs non-US split. | F6: Model card. | G6: Models | H6: Core
A7: Identity | B7: Total / active params | C7: params_total_b / params_active_b | D7: billions | E7: Total weights vs params active per token (differs for MoE). | F7: Model card. | G7: Models | H7: Core
A8: Identity | B8: Architecture | C8: architecture | D8: text | E8: Dense or MoE; affects memory vs compute profile. | F8: Model card. | G8: Models | H8: Core
A9: Identity | B9: Native context length | C9: native_context_len | D9: tokens | E9: Max context the model was trained/extended to. | F9: Model card / config.json. | G9: Models | H9: Core
A10: Identity | B10: License | C10: license | D10: text | E10: Commercial-use terms. Some 'open' models restrict deployment. | F10: Repo LICENSE. | G10: Models | H10: Core
A11: Serving config | B11: Quantization | C11: quantization | D11: enum | E11: Weight precision: FP16/BF16/FP8/INT8/INT4-AWQ/INT4-GPTQ/MXFP4. | F11: Set at load time. | G11: Perf_Results | H11: Core
A12: Serving config | B12: KV cache dtype | C12: kv_cache_dtype | D12: enum | E12: Precision of the KV cache - drives max concurrency. | F12: Engine flag. | G12: Perf_Results | H12: Core
A13: Serving config | B13: Serving stack | C13: serving_stack | D13: enum | E13: vLLM / TensorRT-LLM / SGLang / NIM. Same model, very different numbers. | F13: Record engine + version. | G13: Perf_Results | H13: Core
A14: Serving config | B14: Tensor parallel size | C14: tp_size | D14: count | E14: GPUs the model is sharded across. | F14: Engine flag. | G14: Perf_Results | H14: Core
A15: Serving config | B15: Pipeline parallel size | C15: pp_size | D15: count | E15: Pipeline stages, if used. | F15: Engine flag. | G15: Perf_Results | H15: Optional
... A78: Environment | B78: Power cap | C78: gpu_power_cap_w | D78: W | E78: Capped GPUs invalidate cross-system comparisons. | F78: nvidia-smi -q -d POWER. | G78: Hardware_Env | H78: Core

Sheet Hardware_Env
A1: Hardware & software environment
A2: Fill once per system or stack change. Every number in Perf_Results is only meaningful alongside this.
A3: Field | B3: Value | C3: Unit | D3: Notes / how to obtain
A4: System
A5: dgx_system_model | C5: text | D5: e.g. DGX H100 / DGX A100 / DGX B200 / DGX Spark
A6: hostname | C6: text | D6: Node identifier.
A7: gpu_model | C7: text | D7: nvidia-smi --query-gpu=name --format=csv
A8: gpu_count | C8: count | D8: GPUs physically present in the node.
A9: gpu_memory_gb_each | C9: GB | D9: e.g. 80 for H100 SXM.
A10: nvlink_nvswitch | C10: text | D10: nvidia-smi topo -m - record NVLink generation / NVSwitch presence.
A11: gpu_power_cap_w | C11: W | D11: nvidia-smi -q -d POWER. Note if it differs from the default.
A12: cpu_model | C12: text | D12: lscpu
A13: cpu_cores | C13: count | D13: Physical cores.
A14: system_ram_gb | C14: GB | D14: free -g
A15: storage_type | C15: text | D15: NVMe local / NFS - affects model load time only.
A16: network | C16: text | D16: InfiniBand / Ethernet, speed. Matters for multi-node only.
A17: Software
A18: os_version | C18: text | D18: cat /etc/os-release
A19: kernel | C19: text | D19: uname -r
A20: nvidia_driver | C20: text | D20: nvidia-smi --query-gpu=driver_version --format=csv
A21: cuda_version | C21: text | D21: nvcc --version or nvidia-smi header
A22: container_image | C22: text | D22: Full image tag, e.g. nvcr.io/nvidia/tritonserver:xx.yy-py3
A23: python_version | C23: text | D23: python -V
A24: torch_version | C24: text | D24: pip show torch
A25: vllm_version | C25: text | D25: pip show vllm
A26: trtllm_version | C26: text | D26: pip show tensorrt_llm
A27: sglang_version | C27: text | D27: pip show sglang
A28: nim_version | C28: text | D28: If serving via NVIDIA NIM.
A29: dcgm_version | C29: text | D29: dcgmi --version - used for power/util sampling.
A30: client_tool | C30: text | D30: genai-perf / vllm bench serve / custom asyncio client + version.
A31: Ollama runtime (auto-filled by run_ollama_bench.py)
A32: ollama_version | C32: text | D32: ollama --version
A33: ollama_host | B33: http://localhost:11434 | C33: url | D33: Endpoint the client hits.
A34: OLLAMA_NUM_PARALLEL | C34: count | D34: CRITICAL: caps real concurrency. Requests above this queue, inflating TTFT. Set it >= your max concurrency or the sweep measures queueing, not the model.
A35: OLLAMA_MAX_LOADED_MODELS | C35: count | D35: Keep at 1 while benchmarking so one model owns the GPUs.
A36: OLLAMA_KEEP_ALIVE | C36: text | D36: Model residency. Use 30m+ so reloads do not pollute timings.
A37: OLLAMA_FLASH_ATTENTION | C37: 0/1 | D37: Changes throughput materially. Record it.
A38: OLLAMA_KV_CACHE_TYPE | C38: text | D38: f16 / q8_0 / q4_0 - KV cache quantization.
A39: OLLAMA_SCHED_SPREAD | C39: 0/1 | D39: 1 = spread layers across all GPUs rather than packing.
A40: OLLAMA_GPU_OVERHEAD | C40: bytes | D40: Reserved VRAM per GPU, if set.
...

Sheet Run_Config
A1: Run configuration - fixed experiment controls
A2: Set these once per campaign and do not change them mid-way. Changing a control invalidates cross-model comparison.
A3: Field | B3: Value | C3: Unit | D3: Notes / how to obtain
A4: Campaign
A5: benchmark_name | B5: DGX open-weight LLM benchmark v1 | C5: text | D5: Free text.
A6: owner | C6: text | D6: Who ran it.
A7: date_start | C7: date | D7: First measurement.
A8: date_end | C8: date | D8: Last measurement.
A9: Sweeps
A10: concurrency_sweep | B10: 1,2,4,8,16,32,64,128 | C10: list | D10: Load points. The knee between throughput and latency is the finding.
A11: isl_osl_pairs | B11: 128/128, 2048/256, 8192/1024, 32768/2048 | C11: list | D11: Input/output token pairs. Short-prompt and long-prompt regimes behave very differently.
A12: quantizations_under_test | B12: BF16, FP8, INT4-AWQ | C12: list | D12: Always include a full-precision baseline to measure the quality delta against.
A13: tp_sizes_under_test | B13: 1,2,4,8 | C13: list | D13: Tensor-parallel sizes to sweep for scaling efficiency.
A14: serving_stacks_under_test | B14: vLLM, TensorRT-LLM | C14: list | D14: Same model on two stacks is a fair and very revealing comparison.
A15: Sampling parameters
A16: temperature_accuracy_runs | B16: 0 | C16: - | D16: Use 0 (greedy) for accuracy. Non-zero makes runs unreproducible.
A17: temperature_creative_runs | B17: 0.7 | C17: - | D17: Only for open-ended generation quality.
A18: top_p | B18: 1 | C18: - | D18: Hold identical across all models.
A19: top_k | B19: -1 | C19: - | D19: -1 / 0 = disabled, engine dependent.
A20: max_output_tokens | B20: 1024 | C20: tokens | D20: Cap. For perf runs pair with ignore_eos so OSL is exact.
A21: seed | B21: 42 | C21: int | D21: Where the engine supports it.
A22: ignore_eos_for_perf | B22: Y | C22: Y/N | D22: Forces the exact output length - essential for clean throughput numbers.
A23: Measurement discipline
A24: warmup_requests | B24: 20 | C24: count | D24: Discarded. Never zero - the first requests pay compile/cache costs.
A25: measurement_repeats | B25: 5 | C25: count | D25: Runs per configuration. Report p50 and spread across repeats.
A26: cooldown_between_runs_s | B26: 60 | C26: s | D26: Let the GPUs return to idle temperature.
A27: dataset_source | B27: ShareGPT + synthetic fixed-length | C27: text | D27: Fixed-length synthetic for clean perf; real traces for realistic mixes.
A28: tokenizer_for_counting | C28: text | D28: One tokenizer for all cost maths, or per-model counts are not comparable.
A29: metrics_sampling_interval_s | B29: 1 | C29: s | D29: DCGM/nvidia-smi polling rate for power and utilisation.
A30: SLA thresholds (define before running)
A31: sla_ttft_p95_ms | B31: 500 | C31: ms | D31: Interactive chat budget. Drives meets_ttft_sla.
A32: sla_tpot_p99_ms | B32: 50 | C32: ms | D32: Per-token budget (~20 tok/s felt speed).
A33: sla_min_output_tps_per_user | B33: 20 | C33: tok/s | D33: Minimum acceptable per-user generation speed. Drives meets_tps_sla.
A34: sla_max_error_rate_pct | B34: 1 | C34: % | D34: Above this the load point does not count as served.
A35: notes | C35: text

Sheet Models
A1: Model registry - open-weight models runnable on the DGX
A2: Closed models (Claude, GPT, Gemini, Grok) are API-only and deliberately absent. Verify hf_repo_id against Hugging Face before pulling - repo names drift between releases.
A4: model_key | B4: display_name | C4: provider | D4: country | E4: bloc | F4: open_weights | G4: params_total_b | H4: params_active_b | I4: architecture | J4: native_context_len | K4: license | L4: hf_repo_id | M4: local_path | N4: ollama_tag | O4: modality | P4: planned_quantizations | Q4: priority | R4: notes
A5: deepseek-v3 | B5: DeepSeek-V3 | C5: DeepSeek | D5: China | E5: Non-US | F5: Y | G5: 671 | H5: 37 | I5: MoE | J5: 128000 | K5: DeepSeek | L5: deepseek-ai/DeepSeek-V3 | N5: deepseek-v3:671b | O5: text | P5: BF16, FP8 | Q5: P0 | R5: Flagship open MoE; needs multi-node or heavy quantization
A6: deepseek-r1 | B6: DeepSeek-R1 | C6: DeepSeek | D6: China | E6: Non-US | F6: Y | G6: 671 | H6: 37 | I6: MoE | J6: 128000 | K6: MIT | L6: deepseek-ai/DeepSeek-R1 | N6: deepseek-r1:70b | O6: text | P6: BF16, FP8 | Q6: P0 | R6: Reasoning; budget for long CoT output lengths
A7: qwen3-235b-a22b | B7: Qwen3-235B-A22B | C7: Alibaba | D7: China | E7: Non-US | F7: Y | G7: 235 | H7: 22 | I7: MoE | J7: 128000 | K7: Apache-2.0 | L7: Qwen/Qwen3-235B-A22B | N7: qwen3:235b-a22b | O7: text | P7: BF16, FP8, INT4-AWQ | Q7: P0 | R7: Strong multilingual incl. Indic
A8: qwen3-32b | B8: Qwen3-32B | C8: Alibaba | D8: China | E8: Non-US | F8: Y | G8: 32 | H8: 32 | I8: Dense | J8: 128000 | K8: Apache-2.0 | L8: Qwen/Qwen3-32B | N8: qwen3:32b | O8: text | P8: BF16, FP8, INT4-AWQ | Q8: P0 | R8: Fits single GPU quantized
A9: llama-3.3-70b | B9: Llama 3.3 70B Instruct | C9: Meta | D9: USA | E9: US | F9: Y | G9: 70 | H9: 70 | I9: Dense | J9: 128000 | K9: Llama 3.3 Community | L9: meta-llama/Llama-3.3-70B-Instruct | N9: llama3.3:70b | O9: text | P9: BF16, FP8, INT4-AWQ | Q9: P0 | R9: De-facto baseline
A10: llama-4-scout | B10: Llama 4 Scout | C10: Meta | D10: USA | E10: US | F10: Y | G10: 109 | H10: 17 | I10: MoE | J10: 10000000 | K10: Llama 4 Community | L10: meta-llama/Llama-4-Scout-17B-16E-Instruct | N10: llama4:scout | O10: text+vision | P10: BF16, FP8 | Q10: P1 | R10: Very long context claim - stress it with RULER
A11: gpt-oss-120b | B11: gpt-oss-120b | C11: OpenAI | D11: USA | E11: US | F11: Y | G11: 117 | H11: 5.1 | I11: MoE | J11: 128000 | K11: Apache-2.0 | L11: openai/gpt-oss-120b | N11: gpt-oss:120b | O11: text | P11: MXFP4 | Q11: P0 | R11: Ships natively in MXFP4
A12: gemma-3-27b | B12: Gemma 3 27B IT | C12: Google | D12: USA | E12: US | F12: Y | G12: 27 | H12: 27 | I12: Dense | J12: 128000 | K12: Gemma | L12: google/gemma-3-27b-it | N12: gemma3:27b | O12: text+vision | P12: BF16, FP8, INT4-AWQ | Q12: P1
A13: phi-4 | B13: Phi-4 | C13: Microsoft | D13: USA | E13: US | F13: Y | G13: 14 | H13: 14 | I13: Dense | J13: 16000 | K13: MIT | L13: microsoft/phi-4 | N13: phi4:14b | O13: text | P13: BF16, FP8 | Q13: P1 | R13: Small-model efficiency reference
A14: nemotron-super-49b | B14: Llama Nemotron Super 49B | C14: NVIDIA | D14: USA | E14: US | F14: Y | G14: 49 | H14: 49 | I14: Dense | J14: 128000 | K14: NVIDIA Open Model | L14: nvidia/Llama-3_3-Nemotron-Super-49B-v1 | O14: text | P14: BF16, FP8 | Q14: P1 | R14: NVIDIA-tuned; expect best TRT-LLM numbers
A15: olmo-2-32b | B15: OLMo 2 32B Instruct | C15: Allen Institute (AI2) | D15: USA | E15: US | F15: Y | G15: 32 | H15: 32 | I15: Dense | J15: 4096 | K15: Apache-2.0 | L15: allenai/OLMo-2-0325-32B-Instruct | O15: text | P15: BF16 | Q15: P2 | R15: Fully open data/training - reproducibility reference
A16: mistral-small-3 | B16: Mistral Small 3.x Instruct | C16: Mistral AI | D16: France | E16: Non-US | F16: Y | G16: 24 | H16: 24 | I16: Dense | J16: 128000 | K16: Apache-2.0 | L16: mistralai/Mistral-Small-24B-Instruct-2501 | N16: mistral-small:24b | O16: text | P16: BF16, FP8, INT4-AWQ | Q16: P0
A17: mixtral-8x22b | B17: Mixtral 8x22B Instruct | C17: Mistral AI | D17: France | E17: Non-US | F17: Y | G17: 141 | H17: 39 | I17: MoE | J17: 65536 | K17: Apache-2.0 | L17: mistralai/Mixtral-8x22B-Instruct-v0.1 | N17: mixtral:8x22b | O17: text | P17: BF16, FP8 | Q17: P2 | R17: Older MoE baseline
A18: glm-4.5 | B18: GLM-4.5 | C18: Zhipu AI / Z.ai | D18: China | E18: Non-US | F18: Y | G18: 355 | H18: 32 | I18: MoE | J18: 128000 | K18: MIT | L18: zai-org/GLM-4.5 | O18: text | P18: BF16, FP8 | Q18: P1 | R18: Strong agentic/tool-use scores
A19: kimi-k2 | B19: Kimi K2 Instruct | C19: Moonshot AI | D19: China | E19: Non-US | F19: Y | G19: 1000 | H19: 32 | I19: MoE | J19: 128000 | K19: Modified MIT | L19: moonshotai/Kimi-K2-Instruct | O19: text | P19: FP8, INT4 | Q19: P1 | R19: Largest open MoE - check it fits before scheduling
A20: minimax-m1 | B20: MiniMax-M1 | C20: MiniMax | D20: China | E20: Non-US | F20: Y | G20: 456 | H20: 46 | I20: MoE | J20: 1000000 | K20: Apache-2.0 | L20: MiniMaxAI/MiniMax-M1-80k | O20: text | P20: BF16 | Q20: P2 | R20: Long-context specialist
A21: internlm3-8b | B21: InternLM3 8B Instruct | C21: Shanghai AI Lab | D21: China | E21: Non-US | F21: Y | G21: 8 | H21: 8 | I21: Dense | J21: 32768 | K21: Apache-2.0 | L21: internlm/internlm3-8b-instruct | O21: text | P21: BF16 | Q21: P2
A22: aya-expanse-32b | B22: Aya Expanse 32B | C22: Cohere | D22: Canada | E22: Non-US | F22: Y | G22: 32 | H22: 32 | I22: Dense | J22: 128000 | K22: CC-BY-NC | L22: CohereLabs/aya-expanse-32b | N22: aya-expanse:32b | O22: text | P22: BF16 | Q22: P1 | R22: Multilingual specialist; NC licence - research only
A23: falcon3-10b | B23: Falcon 3 10B Instruct | C23: TII | D23: UAE | E23: Non-US | F23: Y | G23: 10 | H23: 10 | I23: Dense | J23: 32768 | K23: Falcon LLM | L23: tiiuae/Falcon3-10B-Instruct | N23: falcon3:10b | O23: text | P23: BF16, INT4-AWQ | Q23: P2
A24: jamba-1.5-mini | B24: Jamba 1.5 Mini | C24: AI21 Labs | D24: Israel | E24: Non-US | F24: Y | G24: 52 | H24: 12 | I24: Hybrid SSM-Transformer | J24: 256000 | K24: Jamba Open | L24: ai21labs/AI21-Jamba-1.5-Mini | O24: text | P24: BF16 | Q24: P2 | R24: Mamba hybrid - different memory profile, worth a row
A25: exaone-4-32b | B25: EXAONE 4.0 32B | C25: LG AI Research | D25: South Korea | E25: Non-US | F25: Y | G25: 32 | H25: 32 | I25: Dense | J25: 128000 | K25: EXAONE (NC) | L25: LGAI-EXAONE/EXAONE-4.0-32B | O25: text | P25: BF16 | Q25: P2 | R25: Korean + English
A26: sarvam-m | B26: Sarvam-M | C26: Sarvam AI | D26: India | E26: Non-US | F26: Y | G26: 24 | H26: 24 | I26: Dense | J26: 32768 | K26: Apache-2.0 | L26: sarvamai/sarvam-m | O26: text | P26: BF16 | Q26: P1 | R26: Indic-language specialist - include Indic tasks to make this meaningful
A27: sea-lion-v3 | B27: SEA-LION v3 (Gemma-based) | C27: AI Singapore | D27: Singapore | E27: Non-US | F27: Y | G27: 9 | H27: 9 | I27: Dense | J27: 8192 | K27: Gemma | L27: aisingapore/Gemma-SEA-LION-v3-9B-IT | O27: text | P27: BF16 | Q27: P2 | R27: SE-Asian languages
A29: Sizes, context lengths and repo ids are as-published and must be verified before use. A blank ollama_tag means no confirmed Ollama library tag - supply a community GGUF tag (hf.co/<user>/<repo>:<quant>) or run that model on vLLM. Add rows freely - Summary reads this list.

Sheet Ollama_Pull_Log
A1: Ollama pull / resolve log
A2: Appended by run_ollama_bench.py. A model that failed to pull has no rows in Perf_Results - check here before concluding a model 'scored badly'.
A4: timestamp_utc | B4: model_key | C4: ollama_tag | D4: status | E4: size_gb | F4: quantization_level | G4: parameter_size | H4: family | I4: digest | J4: pull_seconds | K4: error

Sheet Cost_Model
A1: Self-hosted cost model
A2: Drives cost_per_1m_out_usd in Perf_Results. Replace every yellow cell with your real figures.
A4: Item | B4: Value | C4: Unit | D4: Notes
A5: system_capex_usd | B5: 350000 | C5: USD | D5: Purchase price of the DGX node. Source: your invoice.
A6: amortisation_years | B6: 4 | C6: years | D6: Depreciation window used by finance.
A7: gpu_count_in_system | B7: 8 | C7: count | D7: GPUs in the node.
A8: annual_utilisation | B8: 0.7 | C8: % | D8: Fraction of wall-clock the GPUs actually serve traffic.
A9: system_power_kw | B9: 10.2 | C9: kW | D9: Sustained wall power under load. Source: PDU reading.
A10: pue | B10: 1.4 | C10: ratio | D10: Datacentre power usage effectiveness.
A11: electricity_usd_per_kwh | B11: 0.09 | C11: USD/kWh | D11: Blended tariff.
A12: opex_overhead_pct | B12: 0.15 | C12: % | D12: Support contract, rack space, admin - as a fraction of capex/yr.
A14: Derived
A15: annual_capex_usd | B15: =B5/B6 -> 87500 | C15: USD/yr | D15: Straight-line depreciation.
A16: annual_opex_usd | B16: =B5*B12 -> 52500 | C16: USD/yr | D16: Support and facilities.
A17: annual_energy_kwh | B17: =B9*B10*8760*B8 -> 87564.96 | C17: kWh/yr | D17: Power x PUE x hours x utilisation.
A18: annual_energy_usd | B18: =B17*B11 -> 7880.8464 | C18: USD/yr | D18: Energy x tariff.
A19: annual_total_usd | B19: =B15+B16+B18 -> 147880.85 | C19: USD/yr | D19: Capex + opex + energy.
A20: gpu_hours_per_year | B20: =B7*8760*B8 -> 49056 | C20: GPU-hr | D20: Billable GPU-hours actually produced.
A21: cost_per_gpu_hour_usd | B21: =IFERROR(B19/B20,"") -> 3.0145313 | C21: USD | D21: All-in. This is what Perf_Results multiplies by.

Sheet Perf_Results
A1: run_id | B1: timestamp_utc | C1: model_key | D1: quantization | E1: kv_cache_dtype | F1: serving_stack | G1: stack_version | H1: tp_size | I1: pp_size | J1: gpu_type | K1: gpu_count | L1: max_model_len | M1: prefix_caching | N1: scheduler_mode | O1: concurrency | P1: request_rate_rps | Q1: isl_tokens | R1: osl_tokens | S1: num_requests | T1: duration_s | U1: completed_requests | V1: failed_requests | W1: total_input_tokens | X1: total_output_tokens | Y1: ttft_p50_ms | Z1: ttft_p95_ms | AA1: ttft_p99_ms | AB1: tpot_p50_ms | AC1: tpot_p99_ms | AD1: itl_p50_ms | AE1: e2e_p50_ms | AF1: e2e_p95_ms | AG1: e2e_p99_ms | AH1: output_tps_per_request | AI1: total_output_tps | AJ1: total_throughput_tps | AK1: requests_per_s | AL1: gpu_mem_peak_gb | AM1: gpu_util_avg_pct | AN1: gpu_power_avg_w | AO1: gpu_power_peak_w | AP1: model_load_time_s | AQ1: prefix_cache_hit_pct | AR1: error_rate_pct | AS1: output_tps_per_gpu | AT1: energy_wh | AU1: tokens_per_joule | AV1: energy_per_1k_out_tokens_wh | AW1: cost_per_1m_out_usd | AX1: meets_ttft_sla | AY1: meets_tps_sla | AZ1: notes
A2: EXAMPLE-001 | B2: 2026-08-01T10:15:00Z | C2: EXAMPLE-model | D2: FP8 | E2: fp8 | F2: vLLM | G2: 0.9.1 | H2: 2 | I2: 1 | J2: H100-80GB-SXM | K2: 2 | L2: 32768 | M2: on | N2: chunked-prefill | O2: 32 | Q2: 2048 | R2: 256 | S2: 640 | T2: 128.4 | U2: 638 | V2: 2 | W2: 1306624 | X2: 163328 | Y2: 312 | Z2: 480.5 | AA2: 640.2 | AB2: 21.4 | AC2: 38.9 | AD2: 21 | AE2: 5790 | AF2: 7120 | AG2: 8450 | AH2: 46.7 | AI2: 1272 | AJ2: 11447 | AK2: 4.97 | AL2: 71.8 | AM2: 92.4 | AN2: 1240 | AO2: 1390 | AP2: 74.2 | AQ2: 11.3 | AR2: =IFERROR(V2/(U2+V2)*100,"") -> 0.3125 | AS2: =IFERROR(AI2/K2,"") -> 636 | AT2: =IFERROR(IF(AN2="","",AN2*T2/3600),"") -> 44.226667 | AU2: =IFERROR(X2/(AN2*T2),"") -> 1.0258266 | AV2: =IFERROR(AN2*T2/3600/X2*1000,"") -> 0.27078435 | AW2: =IFERROR(Cost_Model!$B$21*K2*T2/3600/X2*1000000,"") -> 1.3165934 | AX2: =IF(ISNUMBER(Z2),IF(Z2<=Run_Config!$B$31,"PASS","FAIL"),"") -> PASS | AY2: =IF(ISNUMBER(AH2),IF(AH2>=Run_Config!$B$33,"PASS","FAIL"),"") -> PASS | AZ2: EXAMPLE ROW - shows expected formats. Delete before real runs (the runner drops run_id starting with EXAMPLE).
AR3: =IFERROR(V3/(U3+V3)*100,"") | AS3: =IFERROR(AI3/K3,"") | AT3: =IFERROR(IF(AN3="","",AN3*T3/3600),"") | AU3: =IFERROR(X3/(AN3*T3),"") | AV3: =IFERROR(AN3*T3/3600/X3*1000,"") | AW3: =IFERROR(Cost_Model!$B$21*K3*T3/3600/X3*1000000,"") | AX3: =IF(ISNUMBER(Z3),IF(Z3<=Run_Config!$B$31,"PASS","FAIL"),"") | AY3: =IF(ISNUMBER(AH3),IF(AH3>=Run_Config!$B$33,"PASS","FAIL"),"")
AR4: =IFERROR(V4/(U4+V4)*100,"") | AS4: =IFERROR(AI4/K4,"") | AT4: =IFERROR(IF(AN4="","",AN4*T4/3600),"") | AU4: =IFERROR(X4/(AN4*T4),"") | AV4: =IFERROR(AN4*T4/3600/X4*1000,"") | AW4: =IFERROR(Cost_Model!$B$21*K4*T4/3600/X4*1000000,"") | AX4: =IF(ISNUMBER(Z4),IF(Z4<=Run_Config!$B$31,"PASS","FAIL"),"") | AY4: =IF(ISNUMBER(AH4),IF(AH4>=Run_Config!$B$33,"PASS","FAIL"),"")
AR5: =IFERROR(V5/(U5+V5)*100,"") | AS5: =IFERROR(AI5/K5,"") | AT5: =IFERROR(IF(AN5="","",AN5*T5/3600),"") | AU5: =IFERROR(X5/(AN5*T5),"") | AV5: =IFERROR(AN5*T5/3600/X5*1000,"") | AW5: =IFERROR(Cost_Model!$B$21*K5*T5/3600/X5*1000000,"") | AX5: =IF(ISNUMBER(Z5),IF(Z5<=Run_Config!$B$31,"PASS","FAIL"),"") | AY5: =IF(ISNUMBER(AH5),IF(AH5>=Run_Config!$B$33,"PASS","FAIL"),"")
AR6: =IFERROR(V6/(U6+V6)*100,"") | AS6: =IFERROR(AI6/K6,"") | AT6: =IFERROR(IF(AN6="","",AN6*T6/3600),"") | AU6: =IFERROR(X6/(AN6*T6),"") | AV6: =IFERROR(AN6*T6/3600/X6*1000,"") | AW6: =IFERROR(Cost_Model!$B$21*K6*T6/3600/X6*1000000,"") | AX6: =IF(ISNUMBER(Z6),IF(Z6<=Run_Config!$B$31,"PASS","FAIL"),"") | AY6: =IF(ISNUMBER(AH6),IF(AH6>=Run_Config!$B$33,"PASS","FAIL"),"")
AR7: =IFERROR(V7/(U7+V7)*100,"") | AS7: =IFERROR(AI7/K7,"") | AT7: =IFERROR(IF(AN7="","",AN7*T7/3600),"") | AU7: =IFERROR(X7/(AN7*T7),"") | AV7: =IFERROR(AN7*T7/3600/X7*1000,"") | AW7: =IFERROR(Cost_Model!$B$21*K7*T7/3600/X7*1000000,"") | AX7: =IF(ISNUMBER(Z7),IF(Z7<=Run_Config!$B$31,"PASS","FAIL"),"") | AY7: =IF(ISNUMBER(AH7),IF(AH7>=Run_Config!$B$33,"PASS","FAIL"),"")
AR8: =IFERROR(V8/(U8+V8)*100,"") | AS8: =IFERROR(AI8/K8,"") | AT8: =IFERROR(IF(AN8="","",AN8*T8/3600),"") | AU8: =IFERROR(X8/(AN8*T8),"") | AV8: =IFERROR(AN8*T8/3600/X8*1000,"") | AW8: =IFERROR(Cost_Model!$B$21*K8*T8/3600/X8*1000000,"") | AX8: =IF(ISNUMBER(Z8),IF(Z8<=Run_Config!$B$31,"PASS","FAIL"),"") | AY8: =IF(ISNUMBER(AH8),IF(AH8>=Run_Config!$B$33,"PASS","FAIL"),"")
AR9: =IFERROR(V9/(U9+V9)*100,"") | AS9: =IFERROR(AI9/K9,"") | AT9: =IFERROR(IF(AN9="","",AN9*T9/3600),"") | AU9: =IFERROR(X9/(AN9*T9),"") | AV9: =IFERROR(AN9*T9/3600/X9*1000,"") | AW9: =IFERROR(Cost_Model!$B$21*K9*T9/3600/X9*1000000,"") | AX9: =IF(ISNUMBER(Z9),IF(Z9<=Run_Config!$B$31,"PASS","FAIL"),"") | AY9: =IF(ISNUMBER(AH9),IF(AH9>=Run_Config!$B$33,"PASS","FAIL"),"")
AR10: =IFERROR(V10/(U10+V10)*100,"") | AS10: =IFERROR(AI10/K10,"") | AT10: =IFERROR(IF(AN10="","",AN10*T10/3600),"") | AU10: =IFERROR(X10/(AN10*T10),"") | AV10: =IFERROR(AN10*T10/3600/X10*1000,"") | AW10: =IFERROR(Cost_Model!$B$21*K10*T10/3600/X10*1000000,"") | AX10: =IF(ISNUMBER(Z10),IF(Z10<=Run_Config!$B$31,"PASS","FAIL"),"") | AY10: =IF(ISNUMBER(AH10),IF(AH10>=Run_Config!$B$33,"PASS","FAIL"),"")
AR11: =IFERROR(V11/(U11+V11)*100,"") | AS11: =IFERROR(AI11/K11,"") | AT11: =IFERROR(IF(AN11="","",AN11*T11/3600),"") | AU11: =IFERROR(X11/(AN11*T11),"") | AV11: =IFERROR(AN11*T11/3600/X11*1000,"") | AW11: =IFERROR(Cost_Model!$B$21*K11*T11/3600/X11*1000000,"") | AX11: =IF(ISNUMBER(Z11),IF(Z11<=Run_Config!$B$31,"PASS","FAIL"),"") | AY11: =IF(ISNUMBER(AH11),IF(AH11>=Run_Config!$B$33,"PASS","FAIL"),"")
AR12: =IFERROR(V12/(U12+V12)*100,"") | AS12: =IFERROR(AI12/K12,"") | AT12: =IFERROR(IF(AN12="","",AN12*T12/3600),"") | AU12: =IFERROR(X12/(AN12*T12),"") | AV12: =IFERROR(AN12*T12/3600/X12*1000,"") | AW12: =IFERROR(Cost_Model!$B$21*K12*T12/3600/X12*1000000,"") | AX12: =IF(ISNUMBER(Z12),IF(Z12<=Run_Config!$B$31,"PASS","FAIL"),"") | AY12: =IF(ISNUMBER(AH12),IF(AH12>=Run_Config!$B$33,"PASS","FAIL"),"")
AR13: =IFERROR(V13/(U13+V13)*100,"") | AS13: =IFERROR(AI13/K13,"") | AT13: =IFERROR(IF(AN13="","",AN13*T13/3600),"") | AU13: =IFERROR(X13/(AN13*T13),"") | AV13: =IFERROR(AN13*T13/3600/X13*1000,"") | AW13: =IFERROR(Cost_Model!$B$21*K13*T13/3600/X13*1000000,"") | AX13: =IF(ISNUMBER(Z13),IF(Z13<=Run_Config!$B$31,"PASS","FAIL"),"") | AY13: =IF(ISNUMBER(AH13),IF(AH13>=Run_Config!$B$33,"PASS","FAIL"),"")
AR14: =IFERROR(V14/(U14+V14)*100,"") | AS14: =IFERROR(AI14/K14,"") | AT14: =IFERROR(IF(AN14="","",AN14*T14/3600),"") | AU14: =IFERROR(X14/(AN14*T14),"") | AV14: =IFERROR(AN14*T14/3600/X14*1000,"") | AW14: =IFERROR(Cost_Model!$B$21*K14*T14/3600/X14*1000000,"") | AX14: =IF(ISNUMBER(Z14),IF(Z14<=Run_Config!$B$31,"PASS","FAIL"),"") | AY14: =IF(ISNUMBER(AH14),IF(AH14>=Run_Config!$B$33,"PASS","FAIL"),"")
... AR400: =IFERROR(V400/(U400+V400)*100,"") | AS400: =IFERROR(AI400/K400,"") | AT400: =IFERROR(IF(AN400="","",AN400*T400/3600),"") | AU400: =IFERROR(X400/(AN400*T400),"") | AV400: =IFERROR(AN400*T400/3600/X400*1000,"") | AW400: =IFERROR(Cost_Model!$B$21*K400*T400/3600/X400*1000000,"") | AX400: =IF(ISNUMBER(Z400),IF(Z400<=Run_Config!$B$31,"PASS","FAIL"),"") | AY400: =IF(ISNUMBER(AH400),IF(AH400>=Run_Config!$B$33,"PASS","FAIL"),"")

Sheet Quality_Results
A1: run_id | B1: timestamp_utc | C1: model_key | D1: quantization | E1: serving_stack | F1: task_suite | G1: task_name | H1: capability | I1: language | J1: n_samples | K1: repeats | L1: temperature | M1: top_p | N1: max_tokens | O1: seed | P1: metric_name | Q1: score_mean | R1: score_stdev | S1: score_min | T1: score_max | U1: pass_at_1 | V1: instruction_compliance_pct | W1: valid_json_rate_pct | X1: refusal_rate_pct | Y1: hallucination_rate_pct | Z1: avg_output_tokens | AA1: avg_latency_s | AB1: judge_model | AC1: harness | AD1: score_ci95_halfwidth | AE1: fp16_baseline_score | AF1: delta_vs_fp16_pct | AG1: notes
A2: EXAMPLE-Q-001 | B2: 2026-08-01T14:02:00Z | C2: EXAMPLE-model | D2: BF16 | E2: vLLM | F2: MMLU-Pro | G2: mmlu_pro_all | H2: knowledge | I2: en | J2: 1000 | K2: 5 | L2: 0 | M2: 1 | N2: 1024 | O2: 42 | P2: accuracy | Q2: 0.712 | R2: 0.453 | S2: 0.701 | T2: 0.722 | V2: 94.2 | W2: 99.1 | X2: 0.4 | Y2: 6.8 | Z2: 214 | AA2: 4.9 | AB2: n/a (exact match) | AC2: lm-eval-harness 0.4.x | AD2: =IFERROR(1.96*R2/SQRT(J2*K2),"") -> 0.012556519 | AE2: =IFERROR(AVERAGEIFS(Q$2:Q$300,C$2:C$300,C2,G$2:G$300,G2,D$2:D$300,"BF16"),"") -> 0.712 | AF2: =IFERROR((Q2-AE2)/AE2*100,"") -> 0 | AG2: EXAMPLE ROW - shows expected formats. Scores stored as fractions (0.712 = 71.2%); percentages stored 0-100.
AD3: =IFERROR(1.96*R3/SQRT(J3*K3),"") | AE3: =IFERROR(AVERAGEIFS(Q$2:Q$300,C$2:C$300,C3,G$2:G$300,G3,D$2:D$300,"BF16"),"") | AF3: =IFERROR((Q3-AE3)/AE3*100,"")
AD4: =IFERROR(1.96*R4/SQRT(J4*K4),"") | AE4: =IFERROR(AVERAGEIFS(Q$2:Q$300,C$2:C$300,C4,G$2:G$300,G4,D$2:D$300,"BF16"),"") | AF4: =IFERROR((Q4-AE4)/AE4*100,"")
AD5: =IFERROR(1.96*R5/SQRT(J5*K5),"") | AE5: =IFERROR(AVERAGEIFS(Q$2:Q$300,C$2:C$300,C5,G$2:G$300,G5,D$2:D$300,"BF16"),"") | AF5: =IFERROR((Q5-AE5)/AE5*100,"")
AD6: =IFERROR(1.96*R6/SQRT(J6*K6),"") | AE6: =IFERROR(AVERAGEIFS(Q$2:Q$300,C$2:C$300,C6,G$2:G$300,G6,D$2:D$300,"BF16"),"") | AF6: =IFERROR((Q6-AE6)/AE6*100,"")
AD7: =IFERROR(1.96*R7/SQRT(J7*K7),"") | AE7: =IFERROR(AVERAGEIFS(Q$2:Q$300,C$2:C$300,C7,G$2:G$300,G7,D$2:D$300,"BF16"),"") | AF7: =IFERROR((Q7-AE7)/AE7*100,"")
AD8: =IFERROR(1.96*R8/SQRT(J8*K8),"") | AE8: =IFERROR(AVERAGEIFS(Q$2:Q$300,C$2:C$300,C8,G$2:G$300,G8,D$2:D$300,"BF16"),"") | AF8: =IFERROR((Q8-AE8)/AE8*100,"")
AD9: =IFERROR(1.96*R9/SQRT(J9*K9),"") | AE9: =IFERROR(AVERAGEIFS(Q$2:Q$300,C$2:C$300,C9,G$2:G$300,G9,D$2:D$300,"BF16"),"") | AF9: =IFERROR((Q9-AE9)/AE9*100,"")
AD10: =IFERROR(1.96*R10/SQRT(J10*K10),"") | AE10: =IFERROR(AVERAGEIFS(Q$2:Q$300,C$2:C$300,C10,G$2:G$300,G10,D$2:D$300,"BF16"),"") | AF10: =IFERROR((Q10-AE10)/AE10*100,"")
AD11: =IFERROR(1.96*R11/SQRT(J11*K11),"") | AE11: =IFERROR(AVERAGEIFS(Q$2:Q$300,C$2:C$300,C11,G$2:G$300,G11,D$2:D$300,"BF16"),"") | AF11: =IFERROR((Q11-AE11)/AE11*100,"")
AD12: =IFERROR(1.96*R12/SQRT(J12*K12),"") | AE12: =IFERROR(AVERAGEIFS(Q$2:Q$300,C$2:C$300,C12,G$2:G$300,G12,D$2:D$300,"BF16"),"") | AF12: =IFERROR((Q12-AE12)/AE12*100,"")
AD13: =IFERROR(1.96*R13/SQRT(J13*K13),"") | AE13: =IFERROR(AVERAGEIFS(Q$2:Q$300,C$2:C$300,C13,G$2:G$300,G13,D$2:D$300,"BF16"),"") | AF13: =IFERROR((Q13-AE13)/AE13*100,"")
AD14: =IFERROR(1.96*R14/SQRT(J14*K14),"") | AE14: =IFERROR(AVERAGEIFS(Q$2:Q$300,C$2:C$300,C14,G$2:G$300,G14,D$2:D$300,"BF16"),"") | AF14: =IFERROR((Q14-AE14)/AE14*100,"")
... AD300: =IFERROR(1.96*R300/SQRT(J300*K300),"") | AE300: =IFERROR(AVERAGEIFS(Q$2:Q$300,C$2:C$300,C300,G$2:G$300,G300,D$2:D$300,"BF16"),"") | AF300: =IFERROR((Q300-AE300)/AE300*100,"")

Sheet Summary
A1: Per-model rollup
A2: All formulas. Model list mirrors the Models sheet; figures aggregate Perf_Results and Quality_Results.
A4: model_key | B4: display_name | C4: provider | D4: country | E4: perf_runs | F4: best_total_output_tps | G4: best_output_tps_per_gpu | H4: ttft_p95_at_c1_ms | I4: avg_gpu_mem_peak_gb | J4: best_tokens_per_joule | K4: min_cost_per_1m_out_usd | L4: avg_error_rate_pct | M4: sla_pass_points | N4: quality_runs | O4: avg_quality_score | P4: avg_delta_vs_fp16_pct
A5: =IF(Models!A5="","",Models!A5) -> deepseek-v3 | B5: =IF(Models!B5="","",Models!B5) -> DeepSeek-V3 | C5: =IF(Models!C5="","",Models!C5) -> DeepSeek | D5: =IF(Models!D5="","",Models!D5) -> China | E5: =COUNTIFS(Perf_Results!$C$2:$C$400,$A5) -> 0 | F5: =IF($E5=0,"",IFERROR(_xlfn.MAXIFS(Perf_Results!$AI$2:$AI$400,Perf_Results!$C$2:$C$400,$A5),"")) | G5: =IF($E5=0,"",IFERROR(_xlfn.MAXIFS(Perf_Results!$AS$2:$AS$400,Perf_Results!$C$2:$C$400,$A5),"")) | H5: =IFERROR(AVERAGEIFS(Perf_Results!$Z$2:$Z$400,Perf_Results!$C$2:$C$400,$A5,Perf_Results!$O$2:$O$400,1),"") | I5: =IFERROR(AVERAGEIFS(Perf_Results!$AL$2:$AL$400,Perf_Results!$C$2:$C$400,$A5),"") | J5: =IF($E5=0,"",IFERROR(_xlfn.MAXIFS(Perf_Results!$AU$2:$AU$400,Perf_Results!$C$2:$C$400,$A5),"")) | K5: =IF($E5=0,"",IFERROR(_xlfn.MINIFS(Perf_Results!$AW$2:$AW$400,Perf_Results!$C$2:$C$400,$A5),"")) | L5: =IFERROR(AVERAGEIFS(Perf_Results!$AR$2:$AR$400,Perf_Results!$C$2:$C$400,$A5),"") | M5: =COUNTIFS(Perf_Results!$C$2:$C$400,$A5,Perf_Results!$AX$2:$AX$400,"PASS",Perf_Results!$AY$2:$AY$400,"PASS") -> 0 | N5: =COUNTIFS(Quality_Results!$C$2:$C$300,$A5) -> 0 | O5: =IFERROR(AVERAGEIFS(Quality_Results!$Q$2:$Q$300,Quality_Results!$C$2:$C$300,$A5),"") | P5: =IFERROR(AVERAGEIFS(Quality_Results!$AF$2:$AF$300,Quality_Results!$C$2:$C$300,$A5),"")
A6: =IF(Models!A6="","",Models!A6) -> deepseek-r1 | B6: =IF(Models!B6="","",Models!B6) -> DeepSeek-R1 | C6: =IF(Models!C6="","",Models!C6) -> DeepSeek | D6: =IF(Models!D6="","",Models!D6) -> China | E6: =COUNTIFS(Perf_Results!$C$2:$C$400,$A6) -> 0 | F6: =IF($E6=0,"",IFERROR(_xlfn.MAXIFS(Perf_Results!$AI$2:$AI$400,Perf_Results!$C$2:$C$400,$A6),"")) | G6: =IF($E6=0,"",IFERROR(_xlfn.MAXIFS(Perf_Results!$AS$2:$AS$400,Perf_Results!$C$2:$C$400,$A6),"")) | H6: =IFERROR(AVERAGEIFS(Perf_Results!$Z$2:$Z$400,Perf_Results!$C$2:$C$400,$A6,Perf_Results!$O$2:$O$400,1),"") | I6: =IFERROR(AVERAGEIFS(Perf_Results!$AL$2:$AL$400,Perf_Results!$C$2:$C$400,$A6),"") | J6: =IF($E6=0,"",IFERROR(_xlfn.MAXIFS(Perf_Results!$AU$2:$AU$400,Perf_Results!$C$2:$C$400,$A6),"")) | K6: =IF($E6=0,"",IFERROR(_xlfn.MINIFS(Perf_Results!$AW$2:$AW$400,Perf_Results!$C$2:$C$400,$A6),"")) | L6: =IFERROR(AVERAGEIFS(Perf_Results!$AR$2:$AR$400,Perf_Results!$C$2:$C$400,$A6),"") | M6: =COUNTIFS(Perf_Results!$C$2:$C$400,$A6,Perf_Results!$AX$2:$AX$400,"PASS",Perf_Results!$AY$2:$AY$400,"PASS") -> 0 | N6: =COUNTIFS(Quality_Results!$C$2:$C$300,$A6) -> 0 | O6: =IFERROR(AVERAGEIFS(Quality_Results!$Q$2:$Q$300,Quality_Results!$C$2:$C$300,$A6),"") | P6: =IFERROR(AVERAGEIFS(Quality_Results!$AF$2:$AF$300,Quality_Results!$C$2:$C$300,$A6),"")
A7: =IF(Models!A7="","",Models!A7) -> qwen3-235b-a22b | B7: =IF(Models!B7="","",Models!B7) -> Qwen3-235B-A22B | C7: =IF(Models!C7="","",Models!C7) -> Alibaba | D7: =IF(Models!D7="","",Models!D7) -> China | E7: =COUNTIFS(Perf_Results!$C$2:$C$400,$A7) -> 0 | F7: =IF($E7=0,"",IFERROR(_xlfn.MAXIFS(Perf_Results!$AI$2:$AI$400,Perf_Results!$C$2:$C$400,$A7),"")) | G7: =IF($E7=0,"",IFERROR(_xlfn.MAXIFS(Perf_Results!$AS$2:$AS$400,Perf_Results!$C$2:$C$400,$A7),"")) | H7: =IFERROR(AVERAGEIFS(Perf_Results!$Z$2:$Z$400,Perf_Results!$C$2:$C$400,$A7,Perf_Results!$O$2:$O$400,1),"") | I7: =IFERROR(AVERAGEIFS(Perf_Results!$AL$2:$AL$400,Perf_Results!$C$2:$C$400,$A7),"") | J7: =IF($E7=0,"",IFERROR(_xlfn.MAXIFS(Perf_Results!$AU$2:$AU$400,Perf_Results!$C$2:$C$400,$A7),"")) | K7: =IF($E7=0,"",IFERROR(_xlfn.MINIFS(Perf_Results!$AW$2:$AW$400,Perf_Results!$C$2:$C$400,$A7),"")) | L7: =IFERROR(AVERAGEIFS(Perf_Results!$AR$2:$AR$400,Perf_Results!$C$2:$C$400,$A7),"") | M7: =COUNTIFS(Perf_Results!$C$2:$C$400,$A7,Perf_Results!$AX$2:$AX$400,"PASS",Perf_Results!$AY$2:$AY$400,"PASS") -> 0 | N7: =COUNTIFS(Quality_Results!$C$2:$C$300,$A7) -> 0 | O7: =IFERROR(AVERAGEIFS(Quality_Results!$Q$2:$Q$300,Quality_Results!$C$2:$C$300,$A7),"") | P7: =IFERROR(AVERAGEIFS(Quality_Results!$AF$2:$AF$300,Quality_Results!$C$2:$C$300,$A7),"")
A8: =IF(Models!A8="","",Models!A8) -> qwen3-32b | B8: =IF(Models!B8="","",Models!B8) -> Qwen3-32B | C8: =IF(Models!C8="","",Models!C8) -> Alibaba | D8: =IF(Models!D8="","",Models!D8) -> China | E8: =COUNTIFS(Perf_Results!$C$2:$C$400,$A8) -> 0 | F8: =IF($E8=0,"",IFERROR(_xlfn.MAXIFS(Perf_Results!$AI$2:$AI$400,Perf_Results!$C$2:$C$400,$A8),"")) | G8: =IF($E8=0,"",IFERROR(_xlfn.MAXIFS(Perf_Results!$AS$2:$AS$400,Perf_Results!$C$2:$C$400,$A8),"")) | H8: =IFERROR(AVERAGEIFS(Perf_Results!$Z$2:$Z$400,Perf_Results!$C$2:$C$400,$A8,Perf_Results!$O$2:$O$400,1),"") | I8: =IFERROR(AVERAGEIFS(Perf_Results!$AL$2:$AL$400,Perf_Results!$C$2:$C$400,$A8),"") | J8: =IF($E8=0,"",IFERROR(_xlfn.MAXIFS(Perf_Results!$AU$2:$AU$400,Perf_Results!$C$2:$C$400,$A8),"")) | K8: =IF($E8=0,"",IFERROR(_xlfn.MINIFS(Perf_Results!$AW$2:$AW$400,Perf_Results!$C$2:$C$400,$A8),"")) | L8: =IFERROR(AVERAGEIFS(Perf_Results!$AR$2:$AR$400,Perf_Results!$C$2:$C$400,$A8),"") | M8: =COUNTIFS(Perf_Results!$C$2:$C$400,$A8,Perf_Results!$AX$2:$AX$400,"PASS",Perf_Results!$AY$2:$AY$400,"PASS") -> 0 | N8: =COUNTIFS(Quality_Results!$C$2:$C$300,$A8) -> 0 | O8: =IFERROR(AVERAGEIFS(Quality_Results!$Q$2:$Q$300,Quality_Results!$C$2:$C$300,$A8),"") | P8: =IFERROR(AVERAGEIFS(Quality_Results!$AF$2:$AF$300,Quality_Results!$C$2:$C$300,$A8),"")
A9: =IF(Models!A9="","",Models!A9) -> llama-3.3-70b | B9: =IF(Models!B9="","",Models!B9) -> Llama 3.3 70B Instruct | C9: =IF(Models!C9="","",Models!C9) -> Meta | D9: =IF(Models!D9="","",Models!D9) -> USA | E9: =COUNTIFS(Perf_Results!$C$2:$C$400,$A9) -> 0 | F9: =IF($E9=0,"",IFERROR(_xlfn.MAXIFS(Perf_Results!$AI$2:$AI$400,Perf_Results!$C$2:$C$400,$A9),"")) | G9: =IF($E9=0,"",IFERROR(_xlfn.MAXIFS(Perf_Results!$AS$2:$AS$400,Perf_Results!$C$2:$C$400,$A9),"")) | H9: =IFERROR(AVERAGEIFS(Perf_Results!$Z$2:$Z$400,Perf_Results!$C$2:$C$400,$A9,Perf_Results!$O$2:$O$400,1),"") | I9: =IFERROR(AVERAGEIFS(Perf_Results!$AL$2:$AL$400,Perf_Results!$C$2:$C$400,$A9),"") | J9: =IF($E9=0,"",IFERROR(_xlfn.MAXIFS(Perf_Results!$AU$2:$AU$400,Perf_Results!$C$2:$C$400,$A9),"")) | K9: =IF($E9=0,"",IFERROR(_xlfn.MINIFS(Perf_Results!$AW$2:$AW$400,Perf_Results!$C$2:$C$400,$A9),"")) | L9: =IFERROR(AVERAGEIFS(Perf_Results!$AR$2:$AR$400,Perf_Results!$C$2:$C$400,$A9),"") | M9: =COUNTIFS(Perf_Results!$C$2:$C$400,$A9,Perf_Results!$AX$2:$AX$400,"PASS",Perf_Results!$AY$2:$AY$400,"PASS") -> 0 | N9: =COUNTIFS(Quality_Results!$C$2:$C$300,$A9) -> 0 | O9: =IFERROR(AVERAGEIFS(Quality_Results!$Q$2:$Q$300,Quality_Results!$C$2:$C$300,$A9),"") | P9: =IFERROR(AVERAGEIFS(Quality_Results!$AF$2:$AF$300,Quality_Results!$C$2:$C$300,$A9),"")
A10: =IF(Models!A10="","",Models!A10) -> llama-4-scout | B10: =IF(Models!B10="","",Models!B10) -> Llama 4 Scout | C10: =IF(Models!C10="","",Models!C10) -> Meta | D10: =IF(Models!D10="","",Models!D10) -> USA | E10: =COUNTIFS(Perf_Results!$C$2:$C$400,$A10) -> 0 | F10: =IF($E10=0,"",IFERROR(_xlfn.MAXIFS(Perf_Results!$AI$2:$AI$400,Perf_Results!$C$2:$C$400,$A10),"")) | G10: =IF($E10=0,"",IFERROR(_xlfn.MAXIFS(Perf_Results!$AS$2:$AS$400,Perf_Results!$C$2:$C$400,$A10),"")) | H10: =IFERROR(AVERAGEIFS(Perf_Results!$Z$2:$Z$400,Perf_Results!$C$2:$C$400,$A10,Perf_Results!$O$2:$O$400,1),"") | I10: =IFERROR(AVERAGEIFS(Perf_Results!$AL$2:$AL$400,Perf_Results!$C$2:$C$400,$A10),"") | J10: =IF($E10=0,"",IFERROR(_xlfn.MAXIFS(Perf_Results!$AU$2:$AU$400,Perf_Results!$C$2:$C$400,$A10),"")) | K10: =IF($E10=0,"",IFERROR(_xlfn.MINIFS(Perf_Results!$AW$2:$AW$400,Perf_Results!$C$2:$C$400,$A10),"")) | L10: =IFERROR(AVERAGEIFS(Perf_Results!$AR$2:$AR$400,Perf_Results!$C$2:$C$400,$A10),"") | M10: =COUNTIFS(Perf_Results!$C$2:$C$400,$A10,Perf_Results!$AX$2:$AX$400,"PASS",Perf_Results!$AY$2:$AY$400,"PASS") -> 0 | N10: =COUNTIFS(Quality_Results!$C$2:$C$300,$A10) -> 0 | O10: =IFERROR(AVERAGEIFS(Quality_Results!$Q$2:$Q$300,Quality_Results!$C$2:$C$300,$A10),"") | P10: =IFERROR(AVERAGEIFS(Quality_Results!$AF$2:$AF$300,Quality_Results!$C$2:$C$300,$A10),"")
A11: =IF(Models!A11="","",Models!A11) -> gpt-oss-120b | B11: =IF(Models!B11="","",Models!B11) -> gpt-oss-120b | C11: =IF(Models!C11="","",Models!C11) -> OpenAI | D11: =IF(Models!D11="","",Models!D11) -> USA | E11: =COUNTIFS(Perf_Results!$C$2:$C$400,$A11) -> 0 | F11: =IF($E11=0,"",IFERROR(_xlfn.MAXIFS(Perf_Results!$AI$2:$AI$400,Perf_Results!$C$2:$C$400,$A11),"")) | G11: =IF($E11=0,"",IFERROR(_xlfn.MAXIFS(Perf_Results!$AS$2:$AS$400,Perf_Results!$C$2:$C$400,$A11),"")) | H11: =IFERROR(AVERAGEIFS(Perf_Results!$Z$2:$Z$400,Perf_Results!$C$2:$C$400,$A11,Perf_Results!$O$2:$O$400,1),"") | I11: =IFERROR(AVERAGEIFS(Perf_Results!$AL$2:$AL$400,Perf_Results!$C$2:$C$400,$A11),"") | J11: =IF($E11=0,"",IFERROR(_xlfn.MAXIFS(Perf_Results!$AU$2:$AU$400,Perf_Results!$C$2:$C$400,$A11),"")) | K11: =IF($E11=0,"",IFERROR(_xlfn.MINIFS(Perf_Results!$AW$2:$AW$400,Perf_Results!$C$2:$C$400,$A11),"")) | L11: =IFERROR(AVERAGEIFS(Perf_Results!$AR$2:$AR$400,Perf_Results!$C$2:$C$400,$A11),"") | M11: =COUNTIFS(Perf_Results!$C$2:$C$400,$A11,Perf_Results!$AX$2:$AX$400,"PASS",Perf_Results!$AY$2:$AY$400,"PASS") -> 0 | N11: =COUNTIFS(Quality_Results!$C$2:$C$300,$A11) -> 0 | O11: =IFERROR(AVERAGEIFS(Quality_Results!$Q$2:$Q$300,Quality_Results!$C$2:$C$300,$A11),"") | P11: =IFERROR(AVERAGEIFS(Quality_Results!$AF$2:$AF$300,Quality_Results!$C$2:$C$300,$A11),"")
A12: =IF(Models!A12="","",Models!A12) -> gemma-3-27b | B12: =IF(Models!B12="","",Models!B12) -> Gemma 3 27B IT | C12: =IF(Models!C12="","",Models!C12) -> Google | D12: =IF(Models!D12="","",Models!D12) -> USA | E12: =COUNTIFS(Perf_Results!$C$2:$C$400,$A12) -> 0 | F12: =IF($E12=0,"",IFERROR(_xlfn.MAXIFS(Perf_Results!$AI$2:$AI$400,Perf_Results!$C$2:$C$400,$A12),"")) | G12: =IF($E12=0,"",IFERROR(_xlfn.MAXIFS(Perf_Results!$AS$2:$AS$400,Perf_Results!$C$2:$C$400,$A12),"")) | H12: =IFERROR(AVERAGEIFS(Perf_Results!$Z$2:$Z$400,Perf_Results!$C$2:$C$400,$A12,Perf_Results!$O$2:$O$400,1),"") | I12: =IFERROR(AVERAGEIFS(Perf_Results!$AL$2:$AL$400,Perf_Results!$C$2:$C$400,$A12),"") | J12: =IF($E12=0,"",IFERROR(_xlfn.MAXIFS(Perf_Results!$AU$2:$AU$400,Perf_Results!$C$2:$C$400,$A12),"")) | K12: =IF($E12=0,"",IFERROR(_xlfn.MINIFS(Perf_Results!$AW$2:$AW$400,Perf_Results!$C$2:$C$400,$A12),"")) | L12: =IFERROR(AVERAGEIFS(Perf_Results!$AR$2:$AR$400,Perf_Results!$C$2:$C$400,$A12),"") | M12: =COUNTIFS(Perf_Results!$C$2:$C$400,$A12,Perf_Results!$AX$2:$AX$400,"PASS",Perf_Results!$AY$2:$AY$400,"PASS") -> 0 | N12: =COUNTIFS(Quality_Results!$C$2:$C$300,$A12) -> 0 | O12: =IFERROR(AVERAGEIFS(Quality_Results!$Q$2:$Q$300,Quality_Results!$C$2:$C$300,$A12),"") | P12: =IFERROR(AVERAGEIFS(Quality_Results!$AF$2:$AF$300,Quality_Results!$C$2:$C$300,$A12),"")
A13: =IF(Models!A13="","",Models!A13) -> phi-4 | B13: =IF(Models!B13="","",Models!B13) -> Phi-4 | C13: =IF(Models!C13="","",Models!C13) -> Microsoft | D13: =IF(Models!D13="","",Models!D13) -> USA | E13: =COUNTIFS(Perf_Results!$C$2:$C$400,$A13) -> 0 | F13: =IF($E13=0,"",IFERROR(_xlfn.MAXIFS(Perf_Results!$AI$2:$AI$400,Perf_Results!$C$2:$C$400,$A13),"")) | G13: =IF($E13=0,"",IFERROR(_xlfn.MAXIFS(Perf_Results!$AS$2:$AS$400,Perf_Results!$C$2:$C$400,$A13),"")) | H13: =IFERROR(AVERAGEIFS(Perf_Results!$Z$2:$Z$400,Perf_Results!$C$2:$C$400,$A13,Perf_Results!$O$2:$O$400,1),"") | I13: =IFERROR(AVERAGEIFS(Perf_Results!$AL$2:$AL$400,Perf_Results!$C$2:$C$400,$A13),"") | J13: =IF($E13=0,"",IFERROR(_xlfn.MAXIFS(Perf_Results!$AU$2:$AU$400,Perf_Results!$C$2:$C$400,$A13),"")) | K13: =IF($E13=0,"",IFERROR(_xlfn.MINIFS(Perf_Results!$AW$2:$AW$400,Perf_Results!$C$2:$C$400,$A13),"")) | L13: =IFERROR(AVERAGEIFS(Perf_Results!$AR$2:$AR$400,Perf_Results!$C$2:$C$400,$A13),"") | M13: =COUNTIFS(Perf_Results!$C$2:$C$400,$A13,Perf_Results!$AX$2:$AX$400,"PASS",Perf_Results!$AY$2:$AY$400,"PASS") -> 0 | N13: =COUNTIFS(Quality_Results!$C$2:$C$300,$A13) -> 0 | O13: =IFERROR(AVERAGEIFS(Quality_Results!$Q$2:$Q$300,Quality_Results!$C$2:$C$300,$A13),"") | P13: =IFERROR(AVERAGEIFS(Quality_Results!$AF$2:$AF$300,Quality_Results!$C$2:$C$300,$A13),"")
A14: =IF(Models!A14="","",Models!A14) -> nemotron-super-49b | B14: =IF(Models!B14="","",Models!B14) -> Llama Nemotron Super 49B | C14: =IF(Models!C14="","",Models!C14) -> NVIDIA | D14: =IF(Models!D14="","",Models!D14) -> USA | E14: =COUNTIFS(Perf_Results!$C$2:$C$400,$A14) -> 0 | F14: =IF($E14=0,"",IFERROR(_xlfn.MAXIFS(Perf_Results!$AI$2:$AI$400,Perf_Results!$C$2:$C$400,$A14),"")) | G14: =IF($E14=0,"",IFERROR(_xlfn.MAXIFS(Perf_Results!$AS$2:$AS$400,Perf_Results!$C$2:$C$400,$A14),"")) | H14: =IFERROR(AVERAGEIFS(Perf_Results!$Z$2:$Z$400,Perf_Results!$C$2:$C$400,$A14,Perf_Results!$O$2:$O$400,1),"") | I14: =IFERROR(AVERAGEIFS(Perf_Results!$AL$2:$AL$400,Perf_Results!$C$2:$C$400,$A14),"") | J14: =IF($E14=0,"",IFERROR(_xlfn.MAXIFS(Perf_Results!$AU$2:$AU$400,Perf_Results!$C$2:$C$400,$A14),"")) | K14: =IF($E14=0,"",IFERROR(_xlfn.MINIFS(Perf_Results!$AW$2:$AW$400,Perf_Results!$C$2:$C$400,$A14),"")) | L14: =IFERROR(AVERAGEIFS(Perf_Results!$AR$2:$AR$400,Perf_Results!$C$2:$C$400,$A14),"") | M14: =COUNTIFS(Perf_Results!$C$2:$C$400,$A14,Perf_Results!$AX$2:$AX$400,"PASS",Perf_Results!$AY$2:$AY$400,"PASS") -> 0 | N14: =COUNTIFS(Quality_Results!$C$2:$C$300,$A14) -> 0 | O14: =IFERROR(AVERAGEIFS(Quality_Results!$Q$2:$Q$300,Quality_Results!$C$2:$C$300,$A14),"") | P14: =IFERROR(AVERAGEIFS(Quality_Results!$AF$2:$AF$300,Quality_Results!$C$2:$C$300,$A14),"")
A15: =IF(Models!A15="","",Models!A15) -> olmo-2-32b | B15: =IF(Models!B15="","",Models!B15) -> OLMo 2 32B Instruct | C15: =IF(Models!C15="","",Models!C15) -> Allen Institute (AI2) | D15: =IF(Models!D15="","",Models!D15) -> USA | E15: =COUNTIFS(Perf_Results!$C$2:$C$400,$A15) -> 0 | F15: =IF($E15=0,"",IFERROR(_xlfn.MAXIFS(Perf_Results!$AI$2:$AI$400,Perf_Results!$C$2:$C$400,$A15),"")) | G15: =IF($E15=0,"",IFERROR(_xlfn.MAXIFS(Perf_Results!$AS$2:$AS$400,Perf_Results!$C$2:$C$400,$A15),"")) | H15: =IFERROR(AVERAGEIFS(Perf_Results!$Z$2:$Z$400,Perf_Results!$C$2:$C$400,$A15,Perf_Results!$O$2:$O$400,1),"") | I15: =IFERROR(AVERAGEIFS(Perf_Results!$AL$2:$AL$400,Perf_Results!$C$2:$C$400,$A15),"") | J15: =IF($E15=0,"",IFERROR(_xlfn.MAXIFS(Perf_Results!$AU$2:$AU$400,Perf_Results!$C$2:$C$400,$A15),"")) | K15: =IF($E15=0,"",IFERROR(_xlfn.MINIFS(Perf_Results!$AW$2:$AW$400,Perf_Results!$C$2:$C$400,$A15),"")) | L15: =IFERROR(AVERAGEIFS(Perf_Results!$AR$2:$AR$400,Perf_Results!$C$2:$C$400,$A15),"") | M15: =COUNTIFS(Perf_Results!$C$2:$C$400,$A15,Perf_Results!$AX$2:$AX$400,"PASS",Perf_Results!$AY$2:$AY$400,"PASS") -> 0 | N15: =COUNTIFS(Quality_Results!$C$2:$C$300,$A15) -> 0 | O15: =IFERROR(AVERAGEIFS(Quality_Results!$Q$2:$Q$300,Quality_Results!$C$2:$C$300,$A15),"") | P15: =IFERROR(AVERAGEIFS(Quality_Results!$AF$2:$AF$300,Quality_Results!$C$2:$C$300,$A15),"")
A16: =IF(Models!A16="","",Models!A16) -> mistral-small-3 | B16: =IF(Models!B16="","",Models!B16) -> Mistral Small 3.x Instruct | C16: =IF(Models!C16="","",Models!C16) -> Mistral AI | D16: =IF(Models!D16="","",Models!D16) -> France | E16: =COUNTIFS(Perf_Results!$C$2:$C$400,$A16) -> 0 | F16: =IF($E16=0,"",IFERROR(_xlfn.MAXIFS(Perf_Results!$AI$2:$AI$400,Perf_Results!$C$2:$C$400,$A16),"")) | G16: =IF($E16=0,"",IFERROR(_xlfn.MAXIFS(Perf_Results!$AS$2:$AS$400,Perf_Results!$C$2:$C$400,$A16),"")) | H16: =IFERROR(AVERAGEIFS(Perf_Results!$Z$2:$Z$400,Perf_Results!$C$2:$C$400,$A16,Perf_Results!$O$2:$O$400,1),"") | I16: =IFERROR(AVERAGEIFS(Perf_Results!$AL$2:$AL$400,Perf_Results!$C$2:$C$400,$A16),"") | J16: =IF($E16=0,"",IFERROR(_xlfn.MAXIFS(Perf_Results!$AU$2:$AU$400,Perf_Results!$C$2:$C$400,$A16),"")) | K16: =IF($E16=0,"",IFERROR(_xlfn.MINIFS(Perf_Results!$AW$2:$AW$400,Perf_Results!$C$2:$C$400,$A16),"")) | L16: =IFERROR(AVERAGEIFS(Perf_Results!$AR$2:$AR$400,Perf_Results!$C$2:$C$400,$A16),"") | M16: =COUNTIFS(Perf_Results!$C$2:$C$400,$A16,Perf_Results!$AX$2:$AX$400,"PASS",Perf_Results!$AY$2:$AY$400,"PASS") -> 0 | N16: =COUNTIFS(Quality_Results!$C$2:$C$300,$A16) -> 0 | O16: =IFERROR(AVERAGEIFS(Quality_Results!$Q$2:$Q$300,Quality_Results!$C$2:$C$300,$A16),"") | P16: =IFERROR(AVERAGEIFS(Quality_Results!$AF$2:$AF$300,Quality_Results!$C$2:$C$300,$A16),"")
... A27: =IF(Models!A27="","",Models!A27) -> sea-lion-v3 | B27: =IF(Models!B27="","",Models!B27) -> SEA-LION v3 (Gemma-based) | C27: =IF(Models!C27="","",Models!C27) -> AI Singapore | D27: =IF(Models!D27="","",Models!D27) -> Singapore | E27: =COUNTIFS(Perf_Results!$C$2:$C$400,$A27) -> 0 | F27: =IF($E27=0,"",IFERROR(_xlfn.MAXIFS(Perf_Results!$AI$2:$AI$400,Perf_Results!$C$2:$C$400,$A27),"")) | G27: =IF($E27=0,"",IFERROR(_xlfn.MAXIFS(Perf_Results!$AS$2:$AS$400,Perf_Results!$C$2:$C$400,$A27),"")) | H27: =IFERROR(AVERAGEIFS(Perf_Results!$Z$2:$Z$400,Perf_Results!$C$2:$C$400,$A27,Perf_Results!$O$2:$O$400,1),"") | I27: =IFERROR(AVERAGEIFS(Perf_Results!$AL$2:$AL$400,Perf_Results!$C$2:$C$400,$A27),"") | J27: =IF($E27=0,"",IFERROR(_xlfn.MAXIFS(Perf_Results!$AU$2:$AU$400,Perf_Results!$C$2:$C$400,$A27),"")) | K27: =IF($E27=0,"",IFERROR(_xlfn.MINIFS(Perf_Results!$AW$2:$AW$400,Perf_Results!$C$2:$C$400,$A27),"")) | L27: =IFERROR(AVERAGEIFS(Perf_Results!$AR$2:$AR$400,Perf_Results!$C$2:$C$400,$A27),"") | M27: =COUNTIFS(Perf_Results!$C$2:$C$400,$A27,Perf_Results!$AX$2:$AX$400,"PASS",Perf_Results!$AY$2:$AY$400,"PASS") -> 0 | N27: =COUNTIFS(Quality_Results!$C$2:$C$300,$A27) -> 0 | O27: =IFERROR(AVERAGEIFS(Quality_Results!$Q$2:$Q$300,Quality_Results!$C$2:$C$300,$A27),"") | P27: =IFERROR(AVERAGEIFS(Quality_Results!$AF$2:$AF$300,Quality_Results!$C$2:$C$300,$A27),"")
A29: best_* = best load point observed. ttft_p95_at_c1 = single-user latency (concurrency = 1). sla_pass_points = load points meeting BOTH SLA thresholds - i.e. usable capacity.
