Workbook

Sheet Summary
A1: LLM Catalogue - Non-Chinese vs Chinese
A2: Snapshot 31 July 2026. Primary source: live OpenRouter model API (365 entries, alias pointers, :batch and :free billing variants removed), plus manually added models that do not route through OpenRouter.
A3: Classification is by lab headquarters, not training data or hosting. Rows with 'UNVERIFIED' in the notes column are open/closed calls I could not confirm - check before relying on them.
A5: Counts
A6: Category | B6: Open weights | C6: Closed / API-only | D6: Total
A7: Non-Chinese | B7: =COUNTIF('Non-Chinese'!$D$5:$D$209,"Open") -> 73 | C7: =COUNTIF('Non-Chinese'!$D$5:$D$209,"Closed") -> 132 | D7: =B7+C7 -> 205
A8: Chinese | B8: =COUNTIF(Chinese!$D$5:$D$118,"Open") -> 90 | C8: =COUNTIF(Chinese!$D$5:$D$118,"Closed") -> 24 | D8: =B8+C8 -> 114
A9: Total | B9: =B7+B8 -> 163 | C9: =C7+C8 -> 156 | D9: =D7+D8 -> 319
A11: Models per lab
A12: Lab | B12: Category | C12: Open | D12: Closed | E12: Total
A13: Alibaba (Qwen) | B13: Chinese | C13: =COUNTIFS(Chinese!$B$5:$B$118,$A13,Chinese!$D$5:$D$118,"Open") -> 34 | D13: =COUNTIFS(Chinese!$B$5:$B$118,$A13,Chinese!$D$5:$D$118,"Closed") -> 14 | E13: =C13+D13 -> 48
A14: Ant Group (InclusionAI) | B14: Chinese | C14: =COUNTIFS(Chinese!$B$5:$B$118,$A14,Chinese!$D$5:$D$118,"Open") -> 3 | D14: =COUNTIFS(Chinese!$B$5:$B$118,$A14,Chinese!$D$5:$D$118,"Closed") -> 0 | E14: =C14+D14 -> 3
A15: Baidu | B15: Chinese | C15: =COUNTIFS(Chinese!$B$5:$B$118,$A15,Chinese!$D$5:$D$118,"Open") -> 1 | D15: =COUNTIFS(Chinese!$B$5:$B$118,$A15,Chinese!$D$5:$D$118,"Closed") -> 1 | E15: =C15+D15 -> 2
A16: ByteDance | B16: Chinese | C16: =COUNTIFS(Chinese!$B$5:$B$118,$A16,Chinese!$D$5:$D$118,"Open") -> 1 | D16: =COUNTIFS(Chinese!$B$5:$B$118,$A16,Chinese!$D$5:$D$118,"Closed") -> 1 | E16: =C16+D16 -> 2
A17: ByteDance Seed | B17: Chinese | C17: =COUNTIFS(Chinese!$B$5:$B$118,$A17,Chinese!$D$5:$D$118,"Open") -> 0 | D17: =COUNTIFS(Chinese!$B$5:$B$118,$A17,Chinese!$D$5:$D$118,"Closed") -> 4 | E17: =C17+D17 -> 4
A18: DeepSeek | B18: Chinese | C18: =COUNTIFS(Chinese!$B$5:$B$118,$A18,Chinese!$D$5:$D$118,"Open") -> 12 | D18: =COUNTIFS(Chinese!$B$5:$B$118,$A18,Chinese!$D$5:$D$118,"Closed") -> 0 | E18: =C18+D18 -> 12
A19: iFlytek | B19: Chinese | C19: =COUNTIFS(Chinese!$B$5:$B$118,$A19,Chinese!$D$5:$D$118,"Open") -> 0 | D19: =COUNTIFS(Chinese!$B$5:$B$118,$A19,Chinese!$D$5:$D$118,"Closed") -> 1 | E19: =C19+D19 -> 1
A20: Kuaishou (Kwaipilot) | B20: Chinese | C20: =COUNTIFS(Chinese!$B$5:$B$118,$A20,Chinese!$D$5:$D$118,"Open") -> 3 | D20: =COUNTIFS(Chinese!$B$5:$B$118,$A20,Chinese!$D$5:$D$118,"Closed") -> 0 | E20: =C20+D20 -> 3
A21: Meituan | B21: Chinese | C21: =COUNTIFS(Chinese!$B$5:$B$118,$A21,Chinese!$D$5:$D$118,"Open") -> 1 | D21: =COUNTIFS(Chinese!$B$5:$B$118,$A21,Chinese!$D$5:$D$118,"Closed") -> 0 | E21: =C21+D21 -> 1
A22: MiniMax | B22: Chinese | C22: =COUNTIFS(Chinese!$B$5:$B$118,$A22,Chinese!$D$5:$D$118,"Open") -> 8 | D22: =COUNTIFS(Chinese!$B$5:$B$118,$A22,Chinese!$D$5:$D$118,"Closed") -> 0 | E22: =C22+D22 -> 8
A23: Moonshot AI | B23: Chinese | C23: =COUNTIFS(Chinese!$B$5:$B$118,$A23,Chinese!$D$5:$D$118,"Open") -> 7 | D23: =COUNTIFS(Chinese!$B$5:$B$118,$A23,Chinese!$D$5:$D$118,"Closed") -> 0 | E23: =C23+D23 -> 7
A24: Nex AGI | B24: Chinese | C24: =COUNTIFS(Chinese!$B$5:$B$118,$A24,Chinese!$D$5:$D$118,"Open") -> 2 | D24: =COUNTIFS(Chinese!$B$5:$B$118,$A24,Chinese!$D$5:$D$118,"Closed") -> 0 | E24: =C24+D24 -> 2
... A30: Zhipu AI / Z.ai | B30: Chinese | C30: =COUNTIFS(Chinese!$B$5:$B$118,$A30,Chinese!$D$5:$D$118,"Open") -> 12 | D30: =COUNTIFS(Chinese!$B$5:$B$118,$A30,Chinese!$D$5:$D$118,"Closed") -> 0 | E30: =C30+D30 -> 12
A31: AI Singapore | B31: Non-Chinese | C31: =COUNTIFS('Non-Chinese'!$B$5:$B$209,$A31,'Non-Chinese'!$D$5:$D$209,"Open") -> 1 | D31: =COUNTIFS('Non-Chinese'!$B$5:$B$209,$A31,'Non-Chinese'!$D$5:$D$209,"Closed") -> 0 | E31: =C31+D31 -> 1
A32: AI21 Labs | B32: Non-Chinese | C32: =COUNTIFS('Non-Chinese'!$B$5:$B$209,$A32,'Non-Chinese'!$D$5:$D$209,"Open") -> 1 | D32: =COUNTIFS('Non-Chinese'!$B$5:$B$209,$A32,'Non-Chinese'!$D$5:$D$209,"Closed") -> 0 | E32: =C32+D32 -> 1
A33: Aion Labs | B33: Non-Chinese | C33: =COUNTIFS('Non-Chinese'!$B$5:$B$209,$A33,'Non-Chinese'!$D$5:$D$209,"Open") -> 1 | D33: =COUNTIFS('Non-Chinese'!$B$5:$B$209,$A33,'Non-Chinese'!$D$5:$D$209,"Closed") -> 3 | E33: =C33+D33 -> 4
A34: Allen Institute for AI | B34: Non-Chinese | C34: =COUNTIFS('Non-Chinese'!$B$5:$B$209,$A34,'Non-Chinese'!$D$5:$D$209,"Open") -> 2 | D34: =COUNTIFS('Non-Chinese'!$B$5:$B$209,$A34,'Non-Chinese'!$D$5:$D$209,"Closed") -> 0 | E34: =C34+D34 -> 2
A35: Amazon | B35: Non-Chinese | C35: =COUNTIFS('Non-Chinese'!$B$5:$B$209,$A35,'Non-Chinese'!$D$5:$D$209,"Open") -> 0 | D35: =COUNTIFS('Non-Chinese'!$B$5:$B$209,$A35,'Non-Chinese'!$D$5:$D$209,"Closed") -> 5 | E35: =C35+D35 -> 5
A36: Anthracite (community) | B36: Non-Chinese | C36: =COUNTIFS('Non-Chinese'!$B$5:$B$209,$A36,'Non-Chinese'!$D$5:$D$209,"Open") -> 1 | D36: =COUNTIFS('Non-Chinese'!$B$5:$B$209,$A36,'Non-Chinese'!$D$5:$D$209,"Closed") -> 0 | E36: =C36+D36 -> 1
A37: Anthropic | B37: Non-Chinese | C37: =COUNTIFS('Non-Chinese'!$B$5:$B$209,$A37,'Non-Chinese'!$D$5:$D$209,"Open") -> 0 | D37: =COUNTIFS('Non-Chinese'!$B$5:$B$209,$A37,'Non-Chinese'!$D$5:$D$209,"Closed") -> 18 | E37: =C37+D37 -> 18
A38: Arcee AI | B38: Non-Chinese | C38: =COUNTIFS('Non-Chinese'!$B$5:$B$209,$A38,'Non-Chinese'!$D$5:$D$209,"Open") -> 2 | D38: =COUNTIFS('Non-Chinese'!$B$5:$B$209,$A38,'Non-Chinese'!$D$5:$D$209,"Closed") -> 0 | E38: =C38+D38 -> 2
A39: Cognitive Computations | B39: Non-Chinese | C39: =COUNTIFS('Non-Chinese'!$B$5:$B$209,$A39,'Non-Chinese'!$D$5:$D$209,"Open") -> 1 | D39: =COUNTIFS('Non-Chinese'!$B$5:$B$209,$A39,'Non-Chinese'!$D$5:$D$209,"Closed") -> 0 | E39: =C39+D39 -> 1
A40: Cohere | B40: Non-Chinese | C40: =COUNTIFS('Non-Chinese'!$B$5:$B$209,$A40,'Non-Chinese'!$D$5:$D$209,"Open") -> 5 | D40: =COUNTIFS('Non-Chinese'!$B$5:$B$209,$A40,'Non-Chinese'!$D$5:$D$209,"Closed") -> 0 | E40: =C40+D40 -> 5
A41: Deep Cogito | B41: Non-Chinese | C41: =COUNTIFS('Non-Chinese'!$B$5:$B$209,$A41,'Non-Chinese'!$D$5:$D$209,"Open") -> 1 | D41: =COUNTIFS('Non-Chinese'!$B$5:$B$209,$A41,'Non-Chinese'!$D$5:$D$209,"Closed") -> 0 | E41: =C41+D41 -> 1
A42: Google DeepMind | B42: Non-Chinese | C42: =COUNTIFS('Non-Chinese'!$B$5:$B$209,$A42,'Non-Chinese'!$D$5:$D$209,"Open") -> 7 | D42: =COUNTIFS('Non-Chinese'!$B$5:$B$209,$A42,'Non-Chinese'!$D$5:$D$209,"Closed") -> 21 | E42: =C42+D42 -> 28
... A69: xAI | B69: Non-Chinese | C69: =COUNTIFS('Non-Chinese'!$B$5:$B$209,$A69,'Non-Chinese'!$D$5:$D$209,"Open") -> 0 | D69: =COUNTIFS('Non-Chinese'!$B$5:$B$209,$A69,'Non-Chinese'!$D$5:$D$209,"Closed") -> 5 | E69: =C69+D69 -> 5
A70: Total | C70: =SUM(C13:C69) -> 163 | D70: =SUM(D13:D69) -> 156 | E70: =SUM(E13:E69) -> 319
A72: Legend
A73: - Open = weights downloadable. Licence still varies widely: MIT/Apache (DeepSeek, GLM, Qwen, gpt-oss) vs restrictive (Llama Community, Gemma Terms, Cohere CC-BY-NC).
A74: - Closed = hosted API only, no weights published.
...

Sheet Parameters
A1: Benchmark parameter dictionary
A2: Every parameter worth measuring, grouped by evaluation axis. 'In workbook' = already defined in build_workbook.py's Parameters sheet. 'NEW - add' = gap identified 31 Jul 2026, not yet in the harness.
A3: Core = collect for every run. Optional = collect where relevant. Read the 'How to Test' sheet for the procedure that produces these numbers.
A5: Axis | B5: Parameter | C5: Field name | D5: Unit | E5: Definition / why it matters | F5: How to measure | G5: Sheet | H5: Priority | I5: Status
A6: ACCURACY
A7: Accuracy | B7: Task accuracy | C7: score_mean | D7: 0-1 | E7: Primary metric for the task suite (accuracy, pass@1, F1). | F7: Deterministic graders in graders.py. | G7: Quality_Results | H7: Core | I7: In workbook
A8: Accuracy | B8: Score dispersion | C8: score_stdev | D8: 0-1 | E8: Stdev over every graded item, not over repeats. | F8: Runner computes it. | G8: Quality_Results | H8: Core | I8: In workbook
A9: Accuracy | B9: 95% confidence interval | C9: score_ci95_halfwidth | D9: pts | E9: 1.96*stdev/sqrt(n*repeats). If two models' intervals overlap they are tied. | F9: Formula. Grow n_samples to narrow it. | G9: Quality_Results | H9: Core | I9: In workbook
A10: Accuracy | B10: Sample size | C10: n_samples | D10: count | E10: Graded items behind the score. 15 gives about +/-22 pts; 100 gives +/-9; 600 gives +/-4. | F10: Suite size. | G10: Quality_Results | H10: Core | I10: In workbook
A11: Accuracy | B11: Repeats | C11: repeats | D11: count | E11: Runs per configuration. | F11: Run_Config. | G11: Quality_Results | H11: Core | I11: In workbook
A12: Accuracy | B12: Metric name | C12: metric_name | D12: text | E12: Which metric score_mean holds - accuracy, pass@1, F1, exec-match. | F12: Runner records it. | G12: Quality_Results | H12: Core | I12: In workbook
A13: Accuracy | B13: Hallucination rate | C13: hallucination_rate_pct | D13: % | E13: Unsupported claims or answers to unanswerable questions. | F13: Grounded QA set (extraction suite). | G13: Quality_Results | H13: Core | I13: In workbook
A14: Accuracy | B14: Quantization delta | C14: delta_vs_fp16_pct | D14: % | E14: Quality lost against the BF16 baseline of the same model. | F14: Formula vs fp16_baseline_score. | G14: Quality_Results | H14: Core | I14: In workbook
A15: Accuracy | B15: Verbosity | C15: avg_output_tokens | D15: tokens | E15: A model answering in 3x the tokens costs 3x to serve. | F15: Harness. | G15: Quality_Results | H15: Core | I15: In workbook
A16: Accuracy | B16: Judge model | C16: judge_model | D16: text | E16: Model used for any LLM-as-judge scoring. Must not be a contestant. | F16: Record it; 'none' for deterministic graders. | G16: Quality_Results | H16: Core | I16: In workbook
A17: Accuracy | B17: Calibration error | C17: ece | D17: 0-1 | E17: Expected calibration error - gap between stated confidence and actual correctness. | F17: Bin predictions by confidence, compare to accuracy. | G17: Quality_Results | H17: Optional | I17: NEW - add
A18: Accuracy | B18: Abstention rate | C18: abstention_rate_pct | D18: % | E18: Says 'I don't know' when it should. High accuracy with zero abstention on unanswerable items is a red flag. | F18: Unanswerable subset of the extraction suite. | G18: Quality_Results | H18: Core | I18: NEW - add
... A24: Accuracy | B24: Prompt-sensitivity | C24: prompt_variant_delta_pct | D24: pts | E24: Score change from a reworded but semantically identical prompt. | F24: Two phrasings of the same suite. | G24: Quality_Results | H24: Optional | I24: NEW - add
A25: LATENCY
A26: Latency | B26: Time to first token | C26: ttft_p50_ms / p95 / p99 | D26: ms | E26: The number a user feels first. | F26: Client, streaming mode only. | G26: Perf_Results | H26: Core | I26: In workbook
A27: Latency | B27: Time per output token | C27: tpot_p50_ms / p99 | D27: ms | E27: Perceived typing speed after the first token. | F27: (e2e - ttft) / (out_tokens - 1). | G27: Perf_Results | H27: Core | I27: In workbook
A28: Latency | B28: Inter-token latency | C28: itl_p50_ms | D28: ms | E28: Gap between consecutive tokens; exposes scheduler stalls. | F28: Timestamp every stream chunk. | G28: Perf_Results | H28: Optional | I28: In workbook
A29: Latency | B29: End to end | C29: e2e_p50_ms / p95 / p99 | D29: ms | E29: Request submit to last token. | F29: Client. | G29: Perf_Results | H29: Core | I29: In workbook
A30: Latency | B30: Per-request output rate | C30: output_tps_per_request | D30: tok/s | E30: Decode speed a single user sees. | F30: Client. | G30: Perf_Results | H30: Core | I30: In workbook
A31: Latency | B31: Total output throughput | C31: total_output_tps | D31: tok/s | E31: System-wide capacity number. | F31: Client. | G31: Perf_Results | H31: Core | I31: In workbook
A32: Latency | B32: Total throughput | C32: total_throughput_tps | D32: tok/s | E32: Input + output tokens/s, comparable across shapes. | F32: Client. | G32: Perf_Results | H32: Core | I32: In workbook
A33: Latency | B33: Requests per second | C33: requests_per_s | D33: req/s | E33: Completed requests/s at this load point. | F33: Client. | G33: Perf_Results | H33: Core | I33: In workbook
A34: Latency | B34: Output tok/s per GPU | C34: output_tps_per_gpu | D34: tok/s | E34: Throughput normalised by GPUs actually used. | F34: Formula. | G34: Perf_Results | H34: Core | I34: In workbook
A35: Latency | B35: Cold start | C35: model_load_time_s | D35: s | E35: Process start to ready-to-serve. | F35: Engine log / Ollama load_duration. | G35: Perf_Results | H35: Optional | I35: In workbook
A36: Latency | B36: Time to first ANSWER token | C36: ttfat_ms | D36: ms | E36: On reasoning models TTFT is meaningless - the user waits through the whole thinking block. This is the real perceived latency. | F36: First token after the </think> boundary. | G36: Perf_Results | H36: Core | I36: NEW - add
A37: Latency | B37: Queue wait vs compute | C37: queue_time_ms | D37: ms | E37: Separates scheduler backlog from model speed. High queue time means you are measuring the server, not the model. | F37: Engine metrics endpoint (vLLM exposes it). | G37: Perf_Results | H37: Optional | I37: NEW - add
... A40: Latency | B40: Streaming vs non-streaming | C40: stream_enabled | D40: Y/N | E40: Non-streaming hides TTFT entirely. Record which mode produced the row. | F40: Client flag. | G40: Perf_Results | H40: Core | I40: NEW - add
A41: REASONING
A42: Reasoning | B42: Reasoning suite accuracy | C42: score_mean where capability='reasoning' | D42: 0-1 | E42: Multi-step word problems, algebra, logic. | F42: prompts/reasoning.jsonl. | G42: Quality_Results | H42: Core | I42: In workbook
A43: Reasoning | B43: Reasoning tokens emitted | C43: reasoning_tokens_mean | D43: tokens | E43: Thinking tokens, counted separately from answer tokens. Drives cost more than anything else on R1/Qwen3/GLM-class models. | F43: usage.reasoning_tokens, or count inside <think> tags. | G43: Quality_Results | H43: Core | I43: NEW - add
A44: Reasoning | B44: Accuracy vs thinking budget | C44: score_at_budget_1k / 4k / 16k | D44: 0-1 | E44: The curve, not one point. Where it flattens is your production max_tokens. | F44: Re-run the suite at three max_tokens caps. | G44: Quality_Results | H44: Core | I44: NEW - add
A45: Reasoning | B45: Overthinking rate | C45: reasoning_tokens_on_trivial | D45: tokens | E45: Thinking tokens spent on questions a 7B answers instantly. Pure waste. | F45: Reasoning tokens on the easiest suite decile. | G45: Quality_Results | H45: Optional | I45: NEW - add
A46: Reasoning | B46: Thinking mode | C46: thinking_mode | D46: on/off/auto | E46: Qwen3 /think, DeepSeek DeepThink, GLM toggle. Score both modes; never compare across them. | F46: Request parameter or prompt prefix. | G46: Quality_Results | H46: Core | I46: NEW - add
A47: Reasoning | B47: Truncation at limit | C47: hit_max_tokens_pct | D47: % | E47: Ran out of budget mid-thought. Produces a confident wrong answer with no error. | F47: finish_reason == 'length'. | G47: Quality_Results | H47: Core | I47: NEW - add
A48: Reasoning | B48: Multi-step task completion | C48: task_completion_pct | D48: % | E48: Full trajectory succeeded, not just the final answer. | F48: Agentic harness with step checks. | G48: Quality_Results | H48: Optional | I48: NEW - add
...

Sheet How to Test
A1: How to test these models
A2: Two paths. A platform login screens candidates cheaply; the API produces numbers you can defend. They answer different questions - do not mix their rows.
A4: Section | B4: Step | C4: What to do | D4: Command / detail
A5: WHICH PATH ANSWERS WHICH QUESTION
A6: Choosing a path | C6: Is this model good enough for my task? | D6: Web UI or API - both valid
A7: Choosing a path | C7: Which of these 5 models is best? | D7: API, scripted. A UI cannot reach n=100
A8: Choosing a path | C8: How fast is it for my users? | D8: API if you will deploy on API; DGX if self-hosting. NEVER from a web UI
A9: Choosing a path | C9: What will it cost? | D9: API list price, or DGX cost_per_1m_out_usd
A10: Choosing a path | C10: Can I fine-tune it? | D10: Neither - it is a license check plus a VRAM calculation
A11: STEP 0 - PREREQUISITES
A12: Prerequisites | B12: 0.1 | C12: Restore the repo. All 21 tracked files are currently deleted in the working tree. | D12: git restore .
A13: Prerequisites | B13: 0.2 | C13: Install dependencies. | D13: pip install openpyxl httpx jsonschema
A14: Prerequisites | B14: 0.3 | C14: Confirm the workbook exists and rebuild only if you have no collected data - rebuilding wipes it. | D14: python build_workbook.py
A15: PATH A - PLATFORM LOGIN (WEB UI)
A16: Path A - purpose | C16: Screening only. Use it to cut 20 candidates to 5. It is not a measurement tool. | D16: Expect +/-22 pts of noise at 15 hand-graded prompts
A17: Path A - where | B17: A.1 | C17: OpenRouter chat - one login, ~300 models, side-by-side comparison. Best single account. | D17: https://openrouter.ai/chat
A18: Path A - where | B18: A.2 | C18: NVIDIA build - open-weight models, and it shows the equivalent API snippet. | D18: https://build.nvidia.com
A19: Path A - where | B19: A.3 | C19: Hugging Face playground - the only route for OLMo, Falcon, EXAONE, Sarvam, SEA-LION. | D19: https://huggingface.co/playground
A20: Path A - where | B20: A.4 | C20: LM Arena - blind side-by-side. Use for calibration, never for scoring. | D20: https://lmarena.ai
A21: Path A - where | B21: A.5 | C21: First-party chat UIs for Chinese labs. | D21: chat.qwen.ai / chat.deepseek.com / chat.z.ai / kimi.com
A22: Path A - protocol | B22: A.6 | C22: RULE 1: new chat per prompt. Prior turns change the answer. | D22: Never run a whole suite in one thread
A23: Path A - protocol | B23: A.7 | C23: RULE 2: turn OFF web search, code interpreter and memory. A UI that silently searches is a RAG system, not the model. Biggest source of false results. | D23: Check the toggles before every session
A24: Path A - protocol | B24: A.8 | C24: RULE 3: record the reasoning toggle. Thinking-on vs thinking-off is not a comparison. | D24: Qwen /think, DeepSeek DeepThink, GLM toggle
A25: Path A - protocol | B25: A.9 | C25: RULE 4: paste prompts verbatim from your own suites - they avoid the public-benchmark contamination problem. | D25: prompts/*.jsonl
A26: Path A - protocol | B26: A.10 | C26: RULE 5: fix the scoring rule before you start. 1 = correct, 0 = not. Grade the answer, not the confidence. | D26: Write it down first
A27: Path A - limits | B27: A.11 | C27: Latency from a UI is your ISP plus their queue plus their frontend. Ignore the stopwatch entirely. | D27: Use Path B or the DGX for any timing
A28: Path A - limits | B28: A.12 | C28: Every consumer UI injects a system prompt that changes refusals, formatting and verbosity. UI refusals are not API refusals. | D28: Record system_prompt_id = 'platform default'
A29: Path A - recording | B29: A.13 | C29: Append hand-graded rows to Quality_Results, stamped so they can never be averaged into scripted runs. | D29: serving_stack=WEB:<platform>, judge_model=human
A30: PATH B - API, OPEN-WEIGHT MODELS
A31: Path B - purpose | C31: The path that produces defensible numbers. Same weights as local, so scores transfer. | D31: run_api_quality.py
A32: Path B - keys | B32: B.1 | C32: Copy the template. .env is gitignored. Never commit a key, never paste one into a chat window. | D32: cp .env.example .env
A33: Path B - keys | B33: B.2 | C33: Three keys cover all 25 registry models: OpenRouter (17), Hugging Face (9), NVIDIA (12). | D33: OPENROUTER_API_KEY / HF_TOKEN / NVIDIA_API_KEY
A34: Path B - keys | B34: B.3 | C34: Add Groq too. No extra coverage, but generous free limits cut wall-clock on a full sweep. | D34: GROQ_API_KEY
A35: Path B - verify | B35: B.4 | C35: Confirm which keys loaded. | D35: python run_api_quality.py --list-providers
A36: Path B - verify | B36: B.5 | C36: Resolve every model id against each provider's /models endpoint. Run before EVERY campaign - ids drift, and a stale id 404s exactly like a model scoring zero. | D36: python run_api_quality.py --check
A37: Path B - verify | B37: B.6 | C37: Expect misses today: mistral-small-24b-instruct-2501 and the Nemotron v1 entries are superseded. --check suggests near matches. | D37: Fix providers.json, re-run --check
A38: Path B - size | B38: B.7 | C38: Print the request count and wall-clock estimate before spending anything. | D38: python run_api_quality.py --dry-run --suites reasoning,knowledge
A39: Path B - run | B39: B.8 | C39: Smoke-test one model on one suite end to end. | D39: python run_api_quality.py --models qwen3-32b --suites reasoning --repeats 1
A40: Path B - run | B40: B.9 | C40: Main sweep across the deterministic suites. | D40: python run_api_quality.py --priority P0 --suites reasoning,knowledge,extraction,instruction_following,structured_output
A41: Path B - run | B41: B.10 | C41: Coding is a separate run - it executes model-written Python. Do it in a container. | D41: python run_api_quality.py --priority P0 --suites coding --allow-code-exec
...

Sheet Prompts
A1: Test prompts
A2: 174 prompts across 8 suites. Green rows already exist in prompts/*.jsonl; amber rows are new and live in prompts_extra/*.jsonl.
A3: Every expected value was verified by feeding an ideal answer through graders.py - all 68 new prompts score 1.0, so a zero in a real run is the model, not the key. Reference solutions for all 8 new coding prompts were executed against their own unit tests before being written here.
A4: To use the new ones: cat prompts_extra/reasoning.jsonl >> prompts/reasoning.jsonl (or leave them in place - quick_ollama_test.py reads both directories and folds them into the same suite).
A6: ID | B6: Suite | C6: Capability | D6: Grader | E6: Max tokens | F6: System prompt | G6: Prompt | H6: Expected | I6: Tags | J6: Source
A7: REASONING (33 prompts)
A8: rea-001 | B8: reasoning | C8: math_word_problem | D8: numeric | E8: 700 | F8: Solve the problem. End your reply with the final answer as a plain number on its own line. | G8: A warehouse receives 3 pallets holding 48 boxes each. Inspection finds 17 damaged boxes, which are removed. The remaining boxes are divided equally among 5 trucks, and any boxes that do not divide evenly stay behind. How many boxes does each truck carry? | H8: {"answer": 25} | I8: arithmetic, multi_step | J8: existing
A9: rea-002 | B9: reasoning | C9: math_word_problem | D9: numeric | E9: 700 | F9: Solve the problem. End your reply with the final answer as a plain number on its own line. | G9: A tank holds 900 litres and is completely full. A drain removes 15 litres per minute while an inlet adds 9 litres per minute. Both run continuously. How many minutes until the tank is empty? | H9: {"answer": 150} | I9: rates | J9: existing
A10: rea-003 | B10: reasoning | C10: math_word_problem | D10: numeric | E10: 700 | F10: Solve the problem. End your reply with the final answer as a plain number on its own line. | G10: An item is priced at 2400. The price is first increased by 15%, then the new price is reduced by 20%. What is the final price? | H10: {"answer": 2208} | I10: percentages, order_of_operations | J10: existing
A11: rea-004 | B11: reasoning | C11: algebra | D11: numeric | E11: 700 | F11: Solve the problem. End your reply with the final answer as a plain number on its own line. | G11: Anil is currently three times as old as Bala. In eight years, Anil will be twice as old as Bala. How old is Bala now? | H11: {"answer": 8} | I11: algebra | J11: existing
A12: rea-005 | B12: reasoning | C12: math_word_problem | D12: numeric | E12: 700 | F12: Solve the problem. End your reply with the final answer as a plain number on its own line. | G12: Worker A completes a job alone in 12 days. Worker B completes the same job alone in 18 days. Working together at those rates, how many days do they take? Give the answer as a decimal. | H12: {"answer": 7.2, "tolerance": 0.01} | I12: rates, fractions | J12: existing
A13: rea-006 | B13: reasoning | C13: arithmetic | D13: numeric | E13: 700 | F13: Solve the problem. End your reply with the final answer as a plain number on its own line. | G13: The mean of six numbers is 24. One of the numbers, 39, is removed. What is the mean of the five numbers that remain? | H13: {"answer": 21} | I13: statistics | J13: existing
A14: rea-007 | B14: reasoning | C14: geometry | D14: numeric | E14: 700 | F14: Solve the problem. End your reply with the final answer as a plain number on its own line. | G14: A rectangle has a perimeter of 46 cm. Its length is 4 cm greater than its width. What is its area in square centimetres? | H14: {"answer": 128.25, "tolerance": 0.01} | I14: geometry | J14: existing
A15: rea-008 | B15: reasoning | C15: number_theory | D15: numeric | E15: 700 | F15: Solve the problem. End your reply with the final answer as a plain number on its own line. | G15: What is the smallest three-digit whole number that is divisible by both 6 and 8? | H15: {"answer": 120} | I15: number_theory | J15: existing
A16: rea-009 | B16: reasoning | C16: pattern | D16: numeric | E16: 700 | F16: Solve the problem. End your reply with the final answer as a plain number on its own line. | G16: A sequence begins 3, 7, 15, 31, 63. Each term follows the same rule applied to the previous term. What is the next term? | H16: {"answer": 127} | I16: sequences | J16: existing
A17: rea-010 | B17: reasoning | C17: combinatorics | D17: numeric | E17: 700 | F17: Solve the problem. End your reply with the final answer as a plain number on its own line. | G17: Nine people attend a meeting. Every person shakes hands exactly once with every other person. How many handshakes take place in total? | H17: {"answer": 36} | I17: combinatorics | J17: existing
A18: rea-011 | B18: reasoning | C18: logic | D18: numeric | E18: 900 | F18: Reason carefully. End your reply with the final answer as a plain number on its own line. | G18: Five people are in a room. Each is either a knight, who always tells the truth, or a knave, who always lies. Person 1 says 'exactly one of us is a knave'. Person 2 says 'exactly two of us are knaves'. Person 3 says 'exactly three of us are knaves'. Person 4 says 'exactly four of us are knaves'. Person 5 says 'exactly five of us are knaves'. How many knaves are in the room? | H18: {"answer": 4} | I18: logic, self_reference | J18: existing
A19: rea-012 | B19: reasoning | C19: math_word_problem | D19: numeric | E19: 700 | F19: Solve the problem. End your reply with the final answer as a plain number on its own line. | G19: A shopkeeper buys 12 pens for a total of 216 and sells each pen for 25. What is the total profit on all 12 pens? | H19: {"answer": 84} | I19: arithmetic | J19: existing
... A40: rea-033 | B40: reasoning | C40: logic | D40: exact_match | E40: 500 | F40: Solve the problem. Reply with the answer alone, no explanation. | G40: A deployment runs every 6 hours starting at 00:00. A backup runs every 8 hours starting at 00:00. At what time do they next coincide after 00:00? Answer in 24-hour HH:MM format. | H40: {"any_of": ["24:00", "00:00"]} | I40: scheduling, lcm | J40: NEW - 31 Jul 2026
A41: KNOWLEDGE (27 prompts)
A42: knw-001 | B42: knowledge | C42: science | D42: multiple_choice | E42: 50 | F42: Answer with a single letter: A, B, C or D. No explanation. | G42: Which gas makes up the largest proportion of Earth's atmosphere by volume? A) Oxygen B) Nitrogen C) Carbon dioxide D) Argon | H42: {"answer": "B"} | I42: chemistry | J42: existing
A43: knw-002 | B43: knowledge | C43: computing | D43: multiple_choice | E43: 50 | F43: Answer with a single letter: A, B, C or D. No explanation. | G43: In Big-O notation, what is the average time complexity of a lookup in a well-distributed hash table? A) O(n) B) O(log n) C) O(1) D) O(n log n) | H43: {"answer": "C"} | I43: algorithms | J43: existing
A44: knw-003 | B44: knowledge | C44: computing | D44: multiple_choice | E44: 50 | F44: Answer with a single letter: A, B, C or D. No explanation. | G44: Which layer of the OSI model does TCP operate at? A) Network B) Transport C) Session D) Data link | H44: {"answer": "B"} | I44: networking | J44: existing
A45: knw-004 | B45: knowledge | C45: science | D45: multiple_choice | E45: 50 | F45: Answer with a single letter: A, B, C or D. No explanation. | G45: What is the powerhouse organelle of a eukaryotic cell, where most ATP is produced? A) Ribosome B) Golgi apparatus C) Mitochondrion D) Lysosome | H45: {"answer": "C"} | I45: biology | J45: existing
A46: knw-005 | B46: knowledge | C46: geography | D46: multiple_choice | E46: 50 | F46: Answer with a single letter: A, B, C or D. No explanation. | G46: Which of these countries does NOT share a land border with India? A) Bhutan B) Nepal C) Sri Lanka D) Bangladesh | H46: {"answer": "C"} | I46: geography, negation | J46: existing
A47: knw-006 | B47: knowledge | C47: computing | D47: multiple_choice | E47: 50 | F47: Answer with a single letter: A, B, C or D. No explanation. | G47: In a relational database, what does the ACID acronym's 'D' stand for? A) Distribution B) Durability C) Determinism D) Delegation | H47: {"answer": "B"} | I47: databases | J47: existing
A48: knw-007 | B48: knowledge | C48: physics | D48: multiple_choice | E48: 50 | F48: Answer with a single letter: A, B, C or D. No explanation. | G48: What is the approximate speed of light in a vacuum? A) 300 km/s B) 3,000 km/s C) 300,000 km/s D) 3,000,000 km/s | H48: {"answer": "C"} | I48: physics | J48: existing
A49: knw-008 | B49: knowledge | C49: computing | D49: multiple_choice | E49: 50 | F49: Answer with a single letter: A, B, C or D. No explanation. | G49: Which data structure operates on a last-in, first-out basis? A) Queue B) Stack C) Linked list D) Heap | H49: {"answer": "B"} | I49: data_structures | J49: existing
A50: knw-009 | B50: knowledge | C50: history | D50: multiple_choice | E50: 50 | F50: Answer with a single letter: A, B, C or D. No explanation. | G50: In which year did the Second World War end in Europe? A) 1943 B) 1944 C) 1945 D) 1946 | H50: {"answer": "C"} | I50: history | J50: existing
A51: knw-010 | B51: knowledge | C51: computing | D51: multiple_choice | E51: 50 | F51: Answer with a single letter: A, B, C or D. No explanation. | G51: What does a GPU's HBM refer to? A) High Bandwidth Memory B) Hybrid Buffer Module C) Hierarchical Block Mapping D) Host Bus Manager | H51: {"answer": "A"} | I51: hardware | J51: existing
A52: knw-011 | B52: knowledge | C52: mathematics | D52: multiple_choice | E52: 50 | F52: Answer with a single letter: A, B, C or D. No explanation. | G52: Which of these numbers is prime? A) 91 B) 87 C) 97 D) 99 | H52: {"answer": "C"} | I52: number_theory | J52: existing
A53: knw-012 | B53: knowledge | C53: computing | D53: multiple_choice | E53: 50 | F53: Answer with a single letter: A, B, C or D. No explanation. | G53: In machine learning, what does the 'attention' mechanism in a transformer primarily compute? A) A convolution over fixed-size windows B) Weighted relationships between all positions in a sequence C) A recurrent hidden state passed left to right D) A fixed positional embedding lookup | H53: {"answer": "B"} | I53: ml | J53: existing
... A68: knw-027 | B68: knowledge | C68: computing | D68: multiple_choice | E68: 50 | F68: Answer with a single letter: A, B, C or D. No explanation. | G68: Which quantization format stores each weight in 4 bits? A) BF16 B) FP8 C) INT4-AWQ D) FP32 | H68: {"answer": "C"} | I68: llm_infra | J68: NEW - 31 Jul 2026
A69: CODING (18 prompts)
A70: cod-001 | B70: coding | C70: code_generation | D70: code_exec | E70: 900 | F70: Write Python only. Output a single code block containing the complete function and nothing else. Do not include example usage or tests. | G70: Write a function `run_length_encode(s: str) -> str` that compresses a string by replacing runs of the same character with the character followed by the run length. Runs of length 1 keep the count. For example 'aaabbc' becomes 'a3b2c1'. An empty string returns an empty string. | H70: {"tests": "assert run_length_encode('aaabbc') == 'a3b2c1'\nassert run_length_encode('') == ''\nassert run_length_encode('x') == 'x1'\nassert run_length_encode('aabbaa') == 'a2b2a2'"} | I70: strings | J70: existing
A71: cod-002 | B71: coding | C71: code_generation | D71: code_exec | E71: 900 | F71: Write Python only. Output a single code block containing the complete function and nothing else. Do not include example usage or tests. | G71: Write a function `merge_intervals(intervals: list) -> list` that takes a list of [start, end] pairs and returns them merged and sorted by start, with overlapping or touching intervals combined. For example [[1,3],[2,6],[8,10]] returns [[1,6],[8,10]]. | H71: {"tests": "assert merge_intervals([[1,3],[2,6],[8,10]]) == [[1,6],[8,10]]\nassert merge_intervals([]) == []\nassert merge_intervals([[5,7],[1,2]]) == [[1,2],[5,7]]\nassert merge_intervals([[1,4],[4,5]]) == [[1,5]]"} | I71: algorithms | J71: existing
A72: cod-003 | B72: coding | C72: code_generation | D72: code_exec | E72: 900 | F72: Write Python only. Output a single code block containing the complete function and nothing else. Do not include example usage or tests. | G72: Write a function `is_balanced(s: str) -> bool` that returns True if every bracket in the string is correctly matched and nested. Consider round, square and curly brackets. Any other character is ignored. | H72: {"tests": "assert is_balanced('(a[b]{c})') is True\nassert is_balanced('([)]') is False\nassert is_balanced('') is True\nassert is_balanced('(((') is False\nassert is_balanced('no brackets here') is True"} | I72: stacks | J72: existing
A73: cod-004 | B73: coding | C73: code_generation | D73: code_exec | E73: 900 | F73: Write Python only. Output a single code block containing the complete function and nothing else. Do not include example usage or tests. | G73: Write a function `top_k_frequent(words: list, k: int) -> list` that returns the k most frequent words, ordered by descending count and, where counts tie, alphabetically ascending. | H73: {"tests": "assert top_k_frequent(['b','a','b','c','a','b'], 2) == ['b','a']\nassert top_k_frequent(['x','y'], 2) == ['x','y']\nassert top_k_frequent(['same','same','tie','tie','z'], 2) == ['same','tie']\nassert top_k_frequent([], 3) == []"} | I73: sorting, tie_breaking | J73: existing
A74: cod-005 | B74: coding | C74: code_generation | D74: code_exec | E74: 900 | F74: Write Python only. Output a single code block containing the complete function and nothing else. Do not include example usage or tests. | G74: Write a function `flatten(nested: list) -> list` that flattens an arbitrarily nested list of integers into a single flat list, preserving order. | H74: {"tests": "assert flatten([1,[2,[3,4]],5]) == [1,2,3,4,5]\nassert flatten([]) == []\nassert flatten([[[[7]]]]) == [7]\nassert flatten([1,[],2]) == [1,2]"} | I74: recursion | J74: existing
A75: cod-006 | B75: coding | C75: code_generation | D75: code_exec | E75: 900 | F75: Write Python only. Output a single code block containing the complete function and nothing else. Do not include example usage or tests. | G75: Write a function `parse_duration(text: str) -> int` that converts a duration string such as '1h30m', '45m', '2h' or '90s' into a total number of seconds. Supported units are h, m and s. Return 0 for an empty string. | H75: {"tests": "assert parse_duration('1h30m') == 5400\nassert parse_duration('45m') == 2700\nassert parse_duration('2h') == 7200\nassert parse_duration('90s') == 90\nassert parse_duration('') == 0\nassert parse_duration('1h1m1s') == 3661"} | I75: parsing | J75: existing
...

Sheet Non-Chinese
A1: Non-Chinese LLMs
A2: Labs headquartered outside China. 'Open' = weights downloadable (licence varies); 'Closed' = API access only.
A4: Model | B4: Lab | C4: Country | D4: Weights | E4: License / Notes | F4: Context (tokens) | G4: Input $/M | H4: Output $/M | I4: API ID / Where | J4: Source
A5: Gemma-SEA-LION v3 9B IT | B5: AI Singapore | C5: Singapore | D5: Open | E5: Gemma Terms - Southeast Asian languages | F5: 8192 | I5: hf: aisingapore/Gemma-SEA-LION-v3-9B-IT | J5: Manual - not on OpenRouter
A6: AI21: Jamba Large 1.7 | B6: AI21 Labs | C6: Israel | D6: Open | E6: Jamba Open Model License | F6: 256000 | G6: 2 | H6: 8 | I6: ai21/jamba-large-1.7 | J6: OpenRouter catalogue
A7: AionLabs: Aion-2.0 | B7: Aion Labs | C7: Israel | D7: Closed | F7: 131072 | G7: 0.8 | H7: 1.6 | I7: aion-labs/aion-2.0 | J7: OpenRouter catalogue
A8: AionLabs: Aion-3.0 | B8: Aion Labs | C8: Israel | D8: Closed | F8: 131072 | G8: 3 | H8: 6 | I8: aion-labs/aion-3.0 | J8: OpenRouter catalogue
A9: AionLabs: Aion-3.0-Mini | B9: Aion Labs | C9: Israel | D9: Closed | F9: 131072 | G9: 0.7 | H9: 1.4 | I9: aion-labs/aion-3.0-mini | J9: OpenRouter catalogue
A10: AionLabs: Aion-RP 1.0 (8B) | B10: Aion Labs | C10: Israel | D10: Open | E10: Llama 3.1 fine-tune | F10: 32768 | G10: 0.8 | H10: 1.6 | I10: aion-labs/aion-rp-llama-3.1-8b | J10: OpenRouter catalogue
A11: AllenAI: Olmo 3 32B Think | B11: Allen Institute for AI | C11: United States | D11: Open | E11: Apache 2.0 (fully open: data + recipes) | F11: 65536 | G11: 0.15 | H11: 0.5 | I11: allenai/olmo-3-32b-think | J11: OpenRouter catalogue
A12: OLMo 2 32B Instruct | B12: Allen Institute for AI | C12: United States | D12: Open | E12: Apache 2.0 (fully open: data + recipes) | F12: 4096 | I12: hf: allenai/OLMo-2-0325-32B-Instruct | J12: Manual - not on OpenRouter
A13: Amazon: Nova 2 Lite | B13: Amazon | C13: United States | D13: Closed | F13: 1000000 | G13: 0.3 | H13: 2.5 | I13: amazon/nova-2-lite-v1 | J13: OpenRouter catalogue
A14: Amazon: Nova Lite 1.0 | B14: Amazon | C14: United States | D14: Closed | F14: 300000 | G14: 0.06 | H14: 0.24 | I14: amazon/nova-lite-v1 | J14: OpenRouter catalogue
A15: Amazon: Nova Micro 1.0 | B15: Amazon | C15: United States | D15: Closed | F15: 128000 | G15: 0.035 | H15: 0.14 | I15: amazon/nova-micro-v1 | J15: OpenRouter catalogue
A16: Amazon: Nova Premier 1.0 | B16: Amazon | C16: United States | D16: Closed | F16: 1000000 | G16: 2.5 | H16: 12.5 | I16: amazon/nova-premier-v1 | J16: OpenRouter catalogue
A17: Amazon: Nova Pro 1.0 | B17: Amazon | C17: United States | D17: Closed | F17: 300000 | G17: 0.8 | H17: 3.2 | I17: amazon/nova-pro-v1 | J17: OpenRouter catalogue
A18: Magnum v4 72B | B18: Anthracite (community) | C18: Community | D18: Open | E18: Open weights / community fine-tune | F18: 16384 | G18: 3 | H18: 5 | I18: anthracite-org/magnum-v4-72b | J18: OpenRouter catalogue
A19: Anthropic: Claude 3 Haiku | B19: Anthropic | C19: United States | D19: Closed | F19: 200000 | G19: 0.25 | H19: 1.25 | I19: anthropic/claude-3-haiku | J19: OpenRouter catalogue
A20: Anthropic: Claude Fable 5 | B20: Anthropic | C20: United States | D20: Closed | F20: 1000000 | G20: 10 | H20: 50 | I20: anthropic/claude-fable-5 | J20: OpenRouter catalogue
A21: Anthropic: Claude Haiku 4.5 | B21: Anthropic | C21: United States | D21: Closed | F21: 200000 | G21: 1 | H21: 5 | I21: anthropic/claude-haiku-4.5 | J21: OpenRouter catalogue
A22: Anthropic: Claude Opus 4 | B22: Anthropic | C22: United States | D22: Closed | F22: 200000 | G22: 15 | H22: 75 | I22: anthropic/claude-opus-4 | J22: OpenRouter catalogue
A23: Anthropic: Claude Opus 4.1 | B23: Anthropic | C23: United States | D23: Closed | F23: 200000 | G23: 15 | H23: 75 | I23: anthropic/claude-opus-4.1 | J23: OpenRouter catalogue
A24: Anthropic: Claude Opus 4.5 | B24: Anthropic | C24: United States | D24: Closed | F24: 200000 | G24: 5 | H24: 25 | I24: anthropic/claude-opus-4.5 | J24: OpenRouter catalogue
A25: Anthropic: Claude Opus 4.6 | B25: Anthropic | C25: United States | D25: Closed | F25: 1000000 | G25: 5 | H25: 25 | I25: anthropic/claude-opus-4.6 | J25: OpenRouter catalogue
A26: Anthropic: Claude Opus 4.7 | B26: Anthropic | C26: United States | D26: Closed | F26: 1000000 | G26: 5 | H26: 25 | I26: anthropic/claude-opus-4.7 | J26: OpenRouter catalogue
A27: Anthropic: Claude Opus 4.7 (Fast) | B27: Anthropic | C27: United States | D27: Closed | F27: 1000000 | G27: 30 | H27: 150 | I27: anthropic/claude-opus-4.7-fast | J27: OpenRouter catalogue
A28: Anthropic: Claude Opus 4.8 | B28: Anthropic | C28: United States | D28: Closed | F28: 1000000 | G28: 5 | H28: 25 | I28: anthropic/claude-opus-4.8 | J28: OpenRouter catalogue
A29: Anthropic: Claude Opus 4.8 (Fast) | B29: Anthropic | C29: United States | D29: Closed | F29: 1000000 | G29: 10 | H29: 50 | I29: anthropic/claude-opus-4.8-fast | J29: OpenRouter catalogue
A30: Anthropic: Claude Sonnet 4 | B30: Anthropic | C30: United States | D30: Closed | F30: 1000000 | G30: 3 | H30: 15 | I30: anthropic/claude-sonnet-4 | J30: OpenRouter catalogue
... A33: Anthropic: Claude Sonnet 5 | B33: Anthropic | C33: United States | D33: Closed | F33: 1000000 | G33: 2 | H33: 10 | I33: anthropic/claude-sonnet-5 | J33: OpenRouter catalogue
A34: Claude Mythos 5 | B34: Anthropic | C34: United States | D34: Closed | E34: Gated to approved organisations; not publicly routable | I34: Anthropic API (restricted) | J34: Manual - not on OpenRouter
A35: Claude Opus 5 | B35: Anthropic | C35: United States | D35: Closed | F35: 1000000 | G35: 5 | H35: 25 | I35: anthropic/claude-opus-5 | J35: OpenRouter catalogue
A36: Claude Opus 5 (Fast) | B36: Anthropic | C36: United States | D36: Closed | F36: 1000000 | G36: 10 | H36: 50 | I36: anthropic/claude-opus-5-fast | J36: OpenRouter catalogue
A37: Arcee AI: Trinity Large Thinking | B37: Arcee AI | C37: United States | D37: Open | E37: Open weights / community fine-tune | F37: 262144 | G37: 0.22 | H37: 0.85 | I37: arcee-ai/trinity-large-thinking | J37: OpenRouter catalogue
A38: Arcee AI: Virtuoso Large | B38: Arcee AI | C38: United States | D38: Open | E38: Open weights / community fine-tune | F38: 131072 | G38: 0.75 | H38: 1.2 | I38: arcee-ai/virtuoso-large | J38: OpenRouter catalogue
A39: Venice: Uncensored | B39: Cognitive Computations | C39: United States | D39: Open | E39: Open weights / community fine-tune | F39: 128000 | G39: 0.2 | H39: 0.9 | I39: cognitivecomputations/dolphin-mistral-24b-venice-edition | J39: OpenRouter catalogue
A40: Aya Expanse 32B | B40: Cohere | C40: Canada | D40: Open | E40: CC-BY-NC 4.0 - 23 languages | F40: 128000 | I40: cohere: c4ai-aya-expanse-32b | J40: Manual - not on OpenRouter
A41: Cohere: Command A | B41: Cohere | C41: Canada | D41: Open | E41: CC-BY-NC 4.0 (non-commercial) | F41: 256000 | G41: 2.5 | H41: 10 | I41: cohere/command-a | J41: OpenRouter catalogue
A42: Cohere: Command R (08-2024) | B42: Cohere | C42: Canada | D42: Open | E42: CC-BY-NC 4.0 (non-commercial) | F42: 128000 | G42: 0.15 | H42: 0.6 | I42: cohere/command-r-08-2024 | J42: OpenRouter catalogue
A43: Cohere: Command R+ (08-2024) | B43: Cohere | C43: Canada | D43: Open | E43: CC-BY-NC 4.0 (non-commercial) | F43: 128000 | G43: 2.5 | H43: 10 | I43: cohere/command-r-plus-08-2024 | J43: OpenRouter catalogue
...

Sheet Chinese
A1: Chinese LLMs
A2: Labs headquartered in mainland China. Many of these run on Western infrastructure (Groq, Together, Fireworks, NVIDIA NIM) - hosting does not change the classification.
A4: Model | B4: Lab | C4: Country | D4: Weights | E4: License / Notes | F4: Context (tokens) | G4: Input $/M | H4: Output $/M | I4: API ID / Where | J4: Source
A5: Qwen: Qwen Plus 0728 | B5: Alibaba (Qwen) | C5: China | D5: Closed | E5: Hosted tier (Alibaba Cloud / Model Studio) | F5: 1000000 | G5: 0.26 | H5: 0.78 | I5: qwen/qwen-plus-2025-07-28 | J5: OpenRouter catalogue
A6: Qwen: Qwen Plus 0728 (thinking) | B6: Alibaba (Qwen) | C6: China | D6: Closed | E6: Hosted tier (Alibaba Cloud / Model Studio) | F6: 1000000 | G6: 0.4 | H6: 1.2 | I6: qwen/qwen-plus-2025-07-28:thinking | J6: OpenRouter catalogue
A7: Qwen: Qwen-Plus | B7: Alibaba (Qwen) | C7: China | D7: Closed | E7: Hosted tier (Alibaba Cloud / Model Studio) | F7: 1000000 | G7: 0.26 | H7: 0.78 | I7: qwen/qwen-plus | J7: OpenRouter catalogue
A8: Qwen: Qwen3 Max | B8: Alibaba (Qwen) | C8: China | D8: Closed | E8: Hosted tier (Alibaba Cloud / Model Studio) | F8: 262144 | G8: 0.78 | H8: 3.9 | I8: qwen/qwen3-max | J8: OpenRouter catalogue
A9: Qwen: Qwen3 Max Thinking | B9: Alibaba (Qwen) | C9: China | D9: Closed | E9: Hosted tier (Alibaba Cloud / Model Studio) | F9: 262144 | G9: 0.78 | H9: 3.9 | I9: qwen/qwen3-max-thinking | J9: OpenRouter catalogue
A10: Qwen: Qwen3.5 Plus 2026-02-15 | B10: Alibaba (Qwen) | C10: China | D10: Closed | E10: Hosted tier (Alibaba Cloud / Model Studio) | F10: 1000000 | G10: 0.26 | H10: 1.56 | I10: qwen/qwen3.5-plus-02-15 | J10: OpenRouter catalogue
A11: Qwen: Qwen3.5 Plus 2026-04-20 | B11: Alibaba (Qwen) | C11: China | D11: Closed | E11: Hosted tier (Alibaba Cloud / Model Studio) | F11: 1000000 | G11: 0.3 | H11: 1.8 | I11: qwen/qwen3.5-plus-20260420 | J11: OpenRouter catalogue
A12: Qwen: Qwen3.5-Flash | B12: Alibaba (Qwen) | C12: China | D12: Closed | E12: Hosted tier (Alibaba Cloud / Model Studio) | F12: 1000000 | G12: 0.065 | H12: 0.26 | I12: qwen/qwen3.5-flash-02-23 | J12: OpenRouter catalogue
A13: Qwen: Qwen3.6 Flash | B13: Alibaba (Qwen) | C13: China | D13: Closed | E13: Hosted tier (Alibaba Cloud / Model Studio) | F13: 1000000 | G13: 0.1875 | H13: 1.125 | I13: qwen/qwen3.6-flash | J13: OpenRouter catalogue
A14: Qwen: Qwen3.6 Max Preview | B14: Alibaba (Qwen) | C14: China | D14: Closed | E14: Hosted tier (Alibaba Cloud / Model Studio) | F14: 262144 | G14: 1.027 | H14: 6.162 | I14: qwen/qwen3.6-max-preview | J14: OpenRouter catalogue
A15: Qwen: Qwen3.6 Plus | B15: Alibaba (Qwen) | C15: China | D15: Closed | E15: Hosted tier (Alibaba Cloud / Model Studio) | F15: 1000000 | G15: 0.325 | H15: 1.95 | I15: qwen/qwen3.6-plus | J15: OpenRouter catalogue
A16: Qwen: Qwen3.7 Flash | B16: Alibaba (Qwen) | C16: China | D16: Closed | E16: Hosted tier (Alibaba Cloud / Model Studio) | F16: 1000000 | G16: 0.03 | H16: 0.13 | I16: qwen/qwen3.7-flash | J16: OpenRouter catalogue
... A55: inclusionAI: Ring-2.6-1T | B55: Ant Group (InclusionAI) | C55: China | D55: Open | E55: Apache 2.0 (Ling / Ring) | F55: 262144 | G55: 0.075 | H55: 0.625 | I55: inclusionai/ring-2.6-1t | J55: OpenRouter catalogue
A56: ERNIE 5.x (hosted tiers) | B56: Baidu | C56: China | D56: Closed | E56: UNVERIFIED version - Qianfan platform only | I56: Baidu Qianfan | J56: Manual - not on OpenRouter
A57: Baidu: ERNIE 4.5 VL 424B A47B | B57: Baidu | C57: China | D57: Open | E57: Apache 2.0 (ERNIE 4.5) | F57: 123000 | G57: 0.42 | H57: 1.25 | I57: baidu/ernie-4.5-vl-424b-a47b | J57: OpenRouter catalogue
A58: Doubao (hosted tiers) | B58: ByteDance | C58: China | D58: Closed | E58: UNVERIFIED version - Volcano Ark only | I58: Volcano Ark | J58: Manual - not on OpenRouter
A59: ByteDance: UI-TARS 7B | B59: ByteDance | C59: China | D59: Open | E59: Apache 2.0 (UI-TARS) | F59: 128000 | G59: 0.1 | H59: 0.2 | I59: bytedance/ui-tars-1.5-7b | J59: OpenRouter catalogue
A60: ByteDance Seed: Seed 1.6 | B60: ByteDance Seed | C60: China | D60: Closed | E60: Volcano Ark hosted tier | F60: 262144 | G60: 0.25 | H60: 2 | I60: bytedance-seed/seed-1.6 | J60: OpenRouter catalogue
A61: ByteDance Seed: Seed 1.6 Flash | B61: ByteDance Seed | C61: China | D61: Closed | E61: Volcano Ark hosted tier | F61: 262144 | G61: 0.075 | H61: 0.3 | I61: bytedance-seed/seed-1.6-flash | J61: OpenRouter catalogue
A62: ByteDance Seed: Seed-2.0-Lite | B62: ByteDance Seed | C62: China | D62: Closed | E62: Volcano Ark hosted tier | F62: 262144 | G62: 0.25 | H62: 2 | I62: bytedance-seed/seed-2.0-lite | J62: OpenRouter catalogue
A63: ByteDance Seed: Seed-2.0-Mini | B63: ByteDance Seed | C63: China | D63: Closed | E63: Volcano Ark hosted tier | F63: 262144 | G63: 0.1 | H63: 0.4 | I63: bytedance-seed/seed-2.0-mini | J63: OpenRouter catalogue
A64: DeepSeek: DeepSeek V3 | B64: DeepSeek | C64: China | D64: Open | E64: MIT | F64: 163840 | G64: 0.2574 | H64: 1.0287 | I64: deepseek/deepseek-chat | J64: OpenRouter catalogue
A65: DeepSeek: DeepSeek V3 0324 | B65: DeepSeek | C65: China | D65: Open | E65: MIT | F65: 163840 | G65: 0.27 | H65: 1.12 | I65: deepseek/deepseek-chat-v3-0324 | J65: OpenRouter catalogue
A66: DeepSeek: DeepSeek V3.1 | B66: DeepSeek | C66: China | D66: Open | E66: MIT | F66: 163840 | G66: 0.25 | H66: 0.95 | I66: deepseek/deepseek-chat-v3.1 | J66: OpenRouter catalogue
A67: DeepSeek: DeepSeek V3.1 Terminus | B67: DeepSeek | C67: China | D67: Open | E67: MIT | F67: 163840 | G67: 0.27 | H67: 1 | I67: deepseek/deepseek-v3.1-terminus | J67: OpenRouter catalogue
A68: DeepSeek: DeepSeek V3.2 | B68: DeepSeek | C68: China | D68: Open | E68: MIT | F68: 163840 | G68: 0.269 | H68: 0.4 | I68: deepseek/deepseek-v3.2 | J68: OpenRouter catalogue
A69: DeepSeek: DeepSeek V3.2 Exp | B69: DeepSeek | C69: China | D69: Open | E69: MIT | F69: 163840 | G69: 0.27 | H69: 0.41 | I69: deepseek/deepseek-v3.2-exp | J69: OpenRouter catalogue
A70: DeepSeek: DeepSeek V4 Flash | B70: DeepSeek | C70: China | D70: Open | E70: MIT | F70: 1048576 | G70: 0.14 | H70: 0.28 | I70: deepseek/deepseek-v4-flash | J70: OpenRouter catalogue
... A75: DeepSeek: R1 Distill Llama 70B | B75: DeepSeek | C75: China | D75: Open | E75: MIT | F75: 8192 | G75: 0.8 | H75: 0.8 | I75: deepseek/deepseek-r1-distill-llama-70b | J75: OpenRouter catalogue
A76: Spark (Xinghuo) | B76: iFlytek | C76: China | D76: Closed | E76: UNVERIFIED version - domestic API only | I76: iFlytek API | J76: Manual - not on OpenRouter
A77: Kwaipilot: KAT-Coder-Air V2.5 | B77: Kuaishou (Kwaipilot) | C77: China | D77: Open | E77: UNVERIFIED - confirm KAT-Coder weights on Hugging Face | F77: 256000 | G77: 0.15 | H77: 0.6 | I77: kwaipilot/kat-coder-air-v2.5 | J77: OpenRouter catalogue
A78: Kwaipilot: KAT-Coder-Pro V2 | B78: Kuaishou (Kwaipilot) | C78: China | D78: Open | E78: UNVERIFIED - confirm KAT-Coder weights on Hugging Face | F78: 262144 | G78: 0.3 | H78: 1.2 | I78: kwaipilot/kat-coder-pro-v2 | J78: OpenRouter catalogue
A79: Kwaipilot: KAT-Coder-Pro V2.5 | B79: Kuaishou (Kwaipilot) | C79: China | D79: Open | E79: UNVERIFIED - confirm KAT-Coder weights on Hugging Face | F79: 256000 | G79: 0.74 | H79: 2.96 | I79: kwaipilot/kat-coder-pro-v2.5 | J79: OpenRouter catalogue
A80: Meituan: LongCat 2.0 | B80: Meituan | C80: China | D80: Open | E80: UNVERIFIED - confirm weights release for this version | F80: 1048756 | G80: 0.3 | H80: 1.2 | I80: meituan/longcat-2.0 | J80: OpenRouter catalogue
A81: MiniMax: MiniMax M1 | B81: MiniMax | C81: China | D81: Open | E81: Apache 2.0 / MIT | F81: 1000000 | G81: 0.55 | H81: 2.2 | I81: minimax/minimax-m1 | J81: OpenRouter catalogue
A82: MiniMax: MiniMax M2 | B82: MiniMax | C82: China | D82: Open | E82: Apache 2.0 / MIT | F82: 204800 | G82: 0.255 | H82: 1.02 | I82: minimax/minimax-m2 | J82: OpenRouter catalogue
A83: MiniMax: MiniMax M2-her | B83: MiniMax | C83: China | D83: Open | E83: Apache 2.0 / MIT | F83: 65536 | G83: 0.3 | H83: 1.2 | I83: minimax/minimax-m2-her | J83: OpenRouter catalogue
...
